Workbook
Name RD_IB: Raw_Data!$F$2:$F$20001
Name RD_IERR: Raw_Data!$H$2:$H$20001
Name RD_IREF: Raw_Data!$C$2:$C$20001
Name RD_PASS: Raw_Data!$I$2:$I$20001
Name RD_RB: Raw_Data!$D$2:$D$20001
Name RD_RBK: Raw_Data!$E$2:$E$20001
Name RD_STEP: Raw_Data!$A$2:$A$20001
Name RD_VB: Raw_Data!$G$2:$G$20001
Name RD_VBP: Raw_Data!$B$2:$B$20001

Sheet README
A1: BONE_P 恒流源 — LTspice 三参数扫描分析报告
A2: 生成日期 2026-09-21 | 流水线 parse_draft2.py + parse_sweep2.py + merge_sweeps.py + build_xlsx.py | 数据源 Draft2.log + Draft2_sweep.log ×2 | 组合数 12369（三次扫描合并）
A4: §1 数据来源 (Data source) — 两次互补扫描
A5: 仿真类型 | B5: LTspice transient simulation（瞬态仿真，.tran 15m startup）
A6: LTspice 版本 | B6: 26.0.2 for Windows
A7: 扫描 A (Sweep 1) | B7: Draft2.log | RB 10 kΩ … 200 kΩ，步长 1 kΩ（191 点），5730 组；PASS=1 3783 组
A8: 扫描 B (Sweep 2) | B8: (日志已丢失) | RB 210 kΩ … 1 MΩ，步长 10 kΩ（80 点），2400 组；PASS=1 502 组
A9: 扫描 C (Sweep 3) | B9: Draft2_sweep.log | RB 1 MΩ … 10 MΩ，步长 100 kΩ（90 点），2700 组；PASS=1 6 组
A10: 扫描 D (Sweep 4) | B10: refine (1k 步长) | RB 231 kΩ … 759 kΩ，非等步长（逐窗口细分）（63 点），63 组；PASS=1 40 组
A11: 扫描 E (Sweep 5) | B11: refine (100 步长) | RB 13 kΩ … 754 kΩ，非等步长（逐窗口细分）（198 点），216 组；PASS=1 195 组
A12: 扫描 F (Sweep 6) | B12: refine (10 步长) | RB 14 kΩ … 754 kΩ，非等步长（逐窗口细分）（198 点），216 组；PASS=1 216 组
A13: 扫描 G (Sweep 7) | B13: refine (1 步长) | RB 14 kΩ … 754 kΩ，非等步长（逐窗口细分）（207 点），216 组；PASS=1 216 组
A14: 扫描 H (Sweep 8) | B14: refine (10 步长) | RB 14 kΩ … 2 MΩ，非等步长（逐窗口细分）（252 点），270 组；PASS=1 98 组
A15: 扫描 I (Sweep 9) | B15: refine (1 步长) | RB 14 kΩ … 2 MΩ，非等步长（逐窗口细分）（270 点），270 组；PASS=1 127 组
A16: 扫描 J (Sweep 10) | B16: refine (1 步长) | RB 73 kΩ … 2 MΩ，非等步长（逐窗口细分）（189 点），189 组；PASS=1 88 组
... A24: 注意 | B24: Raw_Data 中 Step 列 = 该行在其来源日志中的 .step 序号，Sweep / Source_Log 列标明来源；行序按 VBP → IREF → RB 排序，故 Step 列不单调。
A26: §2 稳态测量区间 (.meas FROM / TO)
A27: 测量指令 | B27: .meas tran IBONE AVG -I(R_BONE) FROM 12m TO 15m
B28: .meas tran VBONE AVG V(BONE_P,BONE_N) FROM 12m TO 15m
A29: 稳态区间 | B29: FROM 12 ms TO 15 ms
A30: 说明 | B30: 瞬态总时长 15 ms（含 startup 启动），取最后 3 ms（12–15 ms）平均值，以避开启动瞬态、保证进入恒流稳态后测量。同理 IERR / PASS 亦基于该区间。
A32: §3 测量量与单位约定
A33: IBONE | B33: R_BONE 电流平均值（.meas AVG -I(R_BONE)）— 日志原始单位 A，Excel 中换算为 µA
A34: VBONE | B34: R_BONE 两端电压平均值 V(BONE_P,BONE_N) — 单位 V
A35: IERR | B35: 恒流误差 — 单位 % （日志 .meas 直接给出）
A36: PASS | B36: 判据标记 — 1 或 0（日志 .meas 直接给出）
A37: 单位 | B37: IREF / IBONE → µA ；RB → Ω 与 kΩ 并列 ；VBONE → V ；IERR → %
A38: 显示 | B38: µA 与 kΩ 一律使用定点小数，不使用科学计数法
A40: §4 PASS 判据与 IERR 定义
A41: IERR 定义 | B41: IERR = 100 × abs(IBONE − IREF) / IREF [%]
A42: PASS 判据 | B42: PASS = 1 当 IERR <= 1.5 ； 否则 PASS = 0 （即 ±1.5% 恒流精度）
A43: 阈值可改 | B43: 阈值存放在 Rmax_Summary 的全局参数区（PASS 判据 IERR ≤ (%) 单元格）；Raw_Data 的 PASS 列是引用该单元格的活公式 —— 改那一个格，全表重算；IERR 已按全精度保存，因此改阈值无需重跑任何仿真。
A44: 与日志的区别 | B44: LTspice 网表里的 .meas PASS 用的是 1% 判据；本表按 1.5% 由 IERR 重新判定，故 Raw_Data 的 PASS 列可能与日志自身的 PASS 值不同。
A45: 一致性验证 | B45: 解析脚本已逐行交叉验证：IERR 与该公式最大偏差 2.5e-10 %pt；按 1.5% 阈值重算 PASS，与 IERR 判定不一致的行数 = 0 （共 12369 行）
A47: §5 Rmax 定义与标记规则（核心）
A48: Rmax 定义 | B48: 在给定 VBP + IREF 下，满足 PASS=1（±1.5% 恒流误差）的【最大已扫描】BONE 负载电阻 RB
A49: 标记 (1) | B49: 精确值，例如 “163 kΩ” → RB 继续增大即 FAIL，属真实临界值
A50: 标记 (2) | B50: “≥10 MΩ (扫描上限)” → 在上限处仍 PASS，结果只是【下限】，真实 Rmax 更大。三次扫描合并后【已无此情形】：30/30 组合已测得真实临界值
A51: 标记 (3) | B51: “N/A (基础误差>1.5%)” → 最小负载 RB=10 kΩ 时 IERR 已 >1.5%，属电路自身的基础恒流误差，【不是】负载能力为 0，严禁写作 Rmax = 0；原始数据完整保留
A52: 数据完整性 | B52: 未对任何缺失仿真点做插值或补数；图表只连接真实仿真点。
...

Sheet Raw_Data
A1: Step | B1: VBP_V | C1: IREF_uA | D1: RB_Ohm | E1: RB_kOhm | F1: IBONE_uA | G1: VBONE_V | H1: IERR_pct | I1: PASS | J1: Sweep | K1: Source_Log
A2: 1 | B2: 3.3 | C2: 10 | D2: 10000 | E2: =D2/1000 -> 10 | F2: 9.869797 | G2: 0.098697922 | H2: 1.3020312 | I2: =IF(H2<=Rmax_Summary!$B$40,1,0) -> 1 | J2: 1 | K2: Draft2.log
A3: 6 | B3: 3.3 | C3: 10 | D3: 11000 | E3: =D3/1000 -> 11 | F3: 9.869768 | G3: 0.1085674 | H3: 1.3023205 | I3: =IF(H3<=Rmax_Summary!$B$40,1,0) -> 1 | J3: 1 | K3: Draft2.log
A4: 11 | B4: 3.3 | C4: 10 | D4: 12000 | E4: =D4/1000 -> 12 | F4: 9.869739 | G4: 0.11843682 | H4: 1.302611 | I4: =IF(H4<=Rmax_Summary!$B$40,1,0) -> 1 | J4: 1 | K4: Draft2.log
A5: 16 | B5: 3.3 | C5: 10 | D5: 13000 | E5: =D5/1000 -> 13 | F5: 9.86971 | G5: 0.12830618 | H5: 1.3029023 | I5: =IF(H5<=Rmax_Summary!$B$40,1,0) -> 1 | J5: 1 | K5: Draft2.log
A6: 21 | B6: 3.3 | C6: 10 | D6: 14000 | E6: =D6/1000 -> 14 | F6: 9.869681 | G6: 0.13817548 | H6: 1.3031936 | I6: =IF(H6<=Rmax_Summary!$B$40,1,0) -> 1 | J6: 1 | K6: Draft2.log
A7: 26 | B7: 3.3 | C7: 10 | D7: 15000 | E7: =D7/1000 -> 15 | F7: 9.869651 | G7: 0.14804472 | H7: 1.3034864 | I7: =IF(H7<=Rmax_Summary!$B$40,1,0) -> 1 | J7: 1 | K7: Draft2.log
A8: 31 | B8: 3.3 | C8: 10 | D8: 16000 | E8: =D8/1000 -> 16 | F8: 9.869622 | G8: 0.15791389 | H8: 1.3037798 | I8: =IF(H8<=Rmax_Summary!$B$40,1,0) -> 1 | J8: 1 | K8: Draft2.log
A9: 36 | B9: 3.3 | C9: 10 | D9: 17000 | E9: =D9/1000 -> 17 | F9: 9.869593 | G9: 0.16778303 | H9: 1.3040736 | I9: =IF(H9<=Rmax_Summary!$B$40,1,0) -> 1 | J9: 1 | K9: Draft2.log
A10: 41 | B10: 3.3 | C10: 10 | D10: 18000 | E10: =D10/1000 -> 18 | F10: 9.869563 | G10: 0.17765209 | H10: 1.3043687 | I10: =IF(H10<=Rmax_Summary!$B$40,1,0) -> 1 | J10: 1 | K10: Draft2.log
A11: 46 | B11: 3.3 | C11: 10 | D11: 19000 | E11: =D11/1000 -> 19 | F11: 9.869534 | G11: 0.18752109 | H11: 1.3046645 | I11: =IF(H11<=Rmax_Summary!$B$40,1,0) -> 1 | J11: 1 | K11: Draft2.log
A12: 51 | B12: 3.3 | C12: 10 | D12: 20000 | E12: =D12/1000 -> 20 | F12: 9.869504 | G12: 0.19739003 | H12: 1.3049604 | I12: =IF(H12<=Rmax_Summary!$B$40,1,0) -> 1 | J12: 1 | K12: Draft2.log
A13: 56 | B13: 3.3 | C13: 10 | D13: 21000 | E13: =D13/1000 -> 21 | F13: 9.869474 | G13: 0.20725891 | H13: 1.3052578 | I13: =IF(H13<=Rmax_Summary!$B$40,1,0) -> 1 | J13: 1 | K13: Draft2.log
... A12370: 2730 | B12370: 15 | C12370: 200 | D12370: 10000000 | E12370: =D12370/1000 -> 10000 | F12370: 1.499451 | G12370: 14.994515 | H12370: 99.250274 | I12370: =IF(H12370<=Rmax_Summary!$B$40,1,0) -> 0 | J12370: 3 | K12370: Draft2_sweep.log

Sheet Rmax_Summary
A1: Rmax_Summary — 最大 BONE 负载电阻 Rmax（满足 IERR ≤ ±1.5% 的最大已扫描 RB）
A2: 数据来源：Raw_Data（解析自 Draft2.log）。扫描范围 RB = 10 kΩ … 10000 kΩ（两种分辨率，1828 个取值）。单位：kΩ。
A3: 本页 Block A 为 Excel 公式（LOOKUP / SUMPRODUCT），替换 Raw_Data 后可自动重算；标记规则见下方图例。
A5: A. 主结果矩阵 — 每格 = 该 BONE_P 电压 + 目标电流下满足 PASS=1 的最大已扫描 RB
A6: BONE_P / V | B6: 10 | C6: 20 | D6: 50 | E6: 100 | F6: 200
A7: 3.3 | B7: =IF(SUMPRODUCT((RD_VBP=$A7)*(RD_IREF=B$6)*(RD_PASS=1))=0,"N/A (基础误差>1.5%)",IF(SUMPRODUCT((RD_VBP=$A7)*(RD_IREF=B$6)*(RD_RB=$B$38)*(RD_PASS=1))>0,"≥"&TEXT($B$38/1000,"General")&" kΩ (扫描上限)",TEXT(LOOKUP(2,1/((RD_VBP=$A7)*(RD_IREF=B$6)*(RD_PASS=1)),RD_RB)/1000,"General")&" kΩ")) -> 317.808 kΩ | C7: =IF(SUMPRODUCT((RD_VBP=$A7)*(RD_IREF=C$6)*(RD_PASS=1))=0,"N/A (基础误差>1.5%)",IF(SUMPRODUCT((RD_VBP=$A7)*(RD_IREF=C$6)*(RD_RB=$B$38)*(RD_PASS=1))>0,"≥"&TEXT($B$38/1000,"General")&" kΩ (扫描上限)",TEXT(LOOKUP(2,1/((RD_VBP=$A7)*(RD_IREF=C$6)*(RD_PASS=1)),RD_RB)/1000,"General")&" kΩ")) -> 164.462 kΩ | D7: =IF(SUMPRODUCT((RD_VBP=$A7)*(RD_IREF=D$6)*(RD_PASS=1))=0,"N/A (基础误差>1.5%)",IF(SUMPRODUCT((RD_VBP=$A7)*(RD_IREF=D$6)*(RD_RB=$B$38)*(RD_PASS=1))>0,"≥"&TEXT($B$38/1000,"General")&" kΩ (扫描上限)",TEXT(LOOKUP(2,1/((RD_VBP=$A7)*(RD_IREF=D$6)*(RD_PASS=1)),RD_RB)/1000,"General")&" kΩ")) -> 63.982 kΩ | E7: =IF(SUMPRODUCT((RD_VBP=$A7)*(RD_IREF=E$6)*(RD_PASS=1))=0,"N/A (基础误差>1.5%)",IF(SUMPRODUCT((RD_VBP=$A7)*(RD_IREF=E$6)*(RD_RB=$B$38)*(RD_PASS=1))>0,"≥"&TEXT($B$38/1000,"General")&" kΩ (扫描上限)",TEXT(LOOKUP(2,1/((RD_VBP=$A7)*(RD_IREF=E$6)*(RD_PASS=1)),RD_RB)/1000,"General")&" kΩ")) -> 30.489 kΩ | F7: =IF(SUMPRODUCT((RD_VBP=$A7)*(RD_IREF=F$6)*(RD_PASS=1))=0,"N/A (基础误差>1.5%)",IF(SUMPRODUCT((RD_VBP=$A7)*(RD_IREF=F$6)*(RD_RB=$B$38)*(RD_PASS=1))>0,"≥"&TEXT($B$38/1000,"General")&" kΩ (扫描上限)",TEXT(LOOKUP(2,1/((RD_VBP=$A7)*(RD_IREF=F$6)*(RD_PASS=1)),RD_RB)/1000,"General")&" kΩ")) -> 13.742 kΩ
A8: 5 | B8: =IF(SUMPRODUCT((RD_VBP=$A8)*(RD_IREF=B$6)*(RD_PASS=1))=0,"N/A (基础误差>1.5%)",IF(SUMPRODUCT((RD_VBP=$A8)*(RD_IREF=B$6)*(RD_RB=$B$38)*(RD_PASS=1))>0,"≥"&TEXT($B$38/1000,"General")&" kΩ (扫描上限)",TEXT(LOOKUP(2,1/((RD_VBP=$A8)*(RD_IREF=B$6)*(RD_PASS=1)),RD_RB)/1000,"General")&" kΩ")) -> 490.087 kΩ | C8: =IF(SUMPRODUCT((RD_VBP=$A8)*(RD_IREF=C$6)*(RD_PASS=1))=0,"N/A (基础误差>1.5%)",IF(SUMPRODUCT((RD_VBP=$A8)*(RD_IREF=C$6)*(RD_RB=$B$38)*(RD_PASS=1))>0,"≥"&TEXT($B$38/1000,"General")&" kΩ (扫描上限)",TEXT(LOOKUP(2,1/((RD_VBP=$A8)*(RD_IREF=C$6)*(RD_PASS=1)),RD_RB)/1000,"General")&" kΩ")) -> 250.755 kΩ | D8: =IF(SUMPRODUCT((RD_VBP=$A8)*(RD_IREF=D$6)*(RD_PASS=1))=0,"N/A (基础误差>1.5%)",IF(SUMPRODUCT((RD_VBP=$A8)*(RD_IREF=D$6)*(RD_RB=$B$38)*(RD_PASS=1))>0,"≥"&TEXT($B$38/1000,"General")&" kΩ (扫描上限)",TEXT(LOOKUP(2,1/((RD_VBP=$A8)*(RD_IREF=D$6)*(RD_PASS=1)),RD_RB)/1000,"General")&" kΩ")) -> 98.499 kΩ | E8: =IF(SUMPRODUCT((RD_VBP=$A8)*(RD_IREF=E$6)*(RD_PASS=1))=0,"N/A (基础误差>1.5%)",IF(SUMPRODUCT((RD_VBP=$A8)*(RD_IREF=E$6)*(RD_RB=$B$38)*(RD_PASS=1))>0,"≥"&TEXT($B$38/1000,"General")&" kΩ (扫描上限)",TEXT(LOOKUP(2,1/((RD_VBP=$A8)*(RD_IREF=E$6)*(RD_PASS=1)),RD_RB)/1000,"General")&" kΩ")) -> 47.748 kΩ | F8: =IF(SUMPRODUCT((RD_VBP=$A8)*(RD_IREF=F$6)*(RD_PASS=1))=0,"N/A (基础误差>1.5%)",IF(SUMPRODUCT((RD_VBP=$A8)*(RD_IREF=F$6)*(RD_RB=$B$38)*(RD_PASS=1))>0,"≥"&TEXT($B$38/1000,"General")&" kΩ (扫描上限)",TEXT(LOOKUP(2,1/((RD_VBP=$A8)*(RD_IREF=F$6)*(RD_PASS=1)),RD_RB)/1000,"General")&" kΩ")) -> 22.371 kΩ
A9: 8 | B9: =IF(SUMPRODUCT((RD_VBP=$A9)*(RD_IREF=B$6)*(RD_PASS=1))=0,"N/A (基础误差>1.5%)",IF(SUMPRODUCT((RD_VBP=$A9)*(RD_IREF=B$6)*(RD_RB=$B$38)*(RD_PASS=1))>0,"≥"&TEXT($B$38/1000,"General")&" kΩ (扫描上限)",TEXT(LOOKUP(2,1/((RD_VBP=$A9)*(RD_IREF=B$6)*(RD_PASS=1)),RD_RB)/1000,"General")&" kΩ")) -> 794.129 kΩ | C9: =IF(SUMPRODUCT((RD_VBP=$A9)*(RD_IREF=C$6)*(RD_PASS=1))=0,"N/A (基础误差>1.5%)",IF(SUMPRODUCT((RD_VBP=$A9)*(RD_IREF=C$6)*(RD_RB=$B$38)*(RD_PASS=1))>0,"≥"&TEXT($B$38/1000,"General")&" kΩ (扫描上限)",TEXT(LOOKUP(2,1/((RD_VBP=$A9)*(RD_IREF=C$6)*(RD_PASS=1)),RD_RB)/1000,"General")&" kΩ")) -> 403.038 kΩ | D9: =IF(SUMPRODUCT((RD_VBP=$A9)*(RD_IREF=D$6)*(RD_PASS=1))=0,"N/A (基础误差>1.5%)",IF(SUMPRODUCT((RD_VBP=$A9)*(RD_IREF=D$6)*(RD_RB=$B$38)*(RD_PASS=1))>0,"≥"&TEXT($B$38/1000,"General")&" kΩ (扫描上限)",TEXT(LOOKUP(2,1/((RD_VBP=$A9)*(RD_IREF=D$6)*(RD_PASS=1)),RD_RB)/1000,"General")&" kΩ")) -> 159.413 kΩ | E9: =IF(SUMPRODUCT((RD_VBP=$A9)*(RD_IREF=E$6)*(RD_PASS=1))=0,"N/A (基础误差>1.5%)",IF(SUMPRODUCT((RD_VBP=$A9)*(RD_IREF=E$6)*(RD_RB=$B$38)*(RD_PASS=1))>0,"≥"&TEXT($B$38/1000,"General")&" kΩ (扫描上限)",TEXT(LOOKUP(2,1/((RD_VBP=$A9)*(RD_IREF=E$6)*(RD_PASS=1)),RD_RB)/1000,"General")&" kΩ")) -> 78.205 kΩ | F9: =IF(SUMPRODUCT((RD_VBP=$A9)*(RD_IREF=F$6)*(RD_PASS=1))=0,"N/A (基础误差>1.5%)",IF(SUMPRODUCT((RD_VBP=$A9)*(RD_IREF=F$6)*(RD_RB=$B$38)*(RD_PASS=1))>0,"≥"&TEXT($B$38/1000,"General")&" kΩ (扫描上限)",TEXT(LOOKUP(2,1/((RD_VBP=$A9)*(RD_IREF=F$6)*(RD_PASS=1)),RD_RB)/1000,"General")&" kΩ")) -> 37.6 kΩ
A10: 10 | B10: =IF(SUMPRODUCT((RD_VBP=$A10)*(RD_IREF=B$6)*(RD_PASS=1))=0,"N/A (基础误差>1.5%)",IF(SUMPRODUCT((RD_VBP=$A10)*(RD_IREF=B$6)*(RD_RB=$B$38)*(RD_PASS=1))>0,"≥"&TEXT($B$38/1000,"General")&" kΩ (扫描上限)",TEXT(LOOKUP(2,1/((RD_VBP=$A10)*(RD_IREF=B$6)*(RD_PASS=1)),RD_RB)/1000,"General")&" kΩ")) -> 996.836 kΩ | C10: =IF(SUMPRODUCT((RD_VBP=$A10)*(RD_IREF=C$6)*(RD_PASS=1))=0,"N/A (基础误差>1.5%)",IF(SUMPRODUCT((RD_VBP=$A10)*(RD_IREF=C$6)*(RD_RB=$B$38)*(RD_PASS=1))>0,"≥"&TEXT($B$38/1000,"General")&" kΩ (扫描上限)",TEXT(LOOKUP(2,1/((RD_VBP=$A10)*(RD_IREF=C$6)*(RD_PASS=1)),RD_RB)/1000,"General")&" kΩ")) -> 504.56 kΩ | D10: =IF(SUMPRODUCT((RD_VBP=$A10)*(RD_IREF=D$6)*(RD_PASS=1))=0,"N/A (基础误差>1.5%)",IF(SUMPRODUCT((RD_VBP=$A10)*(RD_IREF=D$6)*(RD_RB=$B$38)*(RD_PASS=1))>0,"≥"&TEXT($B$38/1000,"General")&" kΩ (扫描上限)",TEXT(LOOKUP(2,1/((RD_VBP=$A10)*(RD_IREF=D$6)*(RD_PASS=1)),RD_RB)/1000,"General")&" kΩ")) -> 200.022 kΩ | E10: =IF(SUMPRODUCT((RD_VBP=$A10)*(RD_IREF=E$6)*(RD_PASS=1))=0,"N/A (基础误差>1.5%)",IF(SUMPRODUCT((RD_VBP=$A10)*(RD_IREF=E$6)*(RD_RB=$B$38)*(RD_PASS=1))>0,"≥"&TEXT($B$38/1000,"General")&" kΩ (扫描上限)",TEXT(LOOKUP(2,1/((RD_VBP=$A10)*(RD_IREF=E$6)*(RD_PASS=1)),RD_RB)/1000,"General")&" kΩ")) -> 98.509 kΩ | F10: =IF(SUMPRODUCT((RD_VBP=$A10)*(RD_IREF=F$6)*(RD_PASS=1))=0,"N/A (基础误差>1.5%)",IF(SUMPRODUCT((RD_VBP=$A10)*(RD_IREF=F$6)*(RD_RB=$B$38)*(RD_PASS=1))>0,"≥"&TEXT($B$38/1000,"General")&" kΩ (扫描上限)",TEXT(LOOKUP(2,1/((RD_VBP=$A10)*(RD_IREF=F$6)*(RD_PASS=1)),RD_RB)/1000,"General")&" kΩ")) -> 47.752 kΩ
A11: 12 | B11: =IF(SUMPRODUCT((RD_VBP=$A11)*(RD_IREF=B$6)*(RD_PASS=1))=0,"N/A (基础误差>1.5%)",IF(SUMPRODUCT((RD_VBP=$A11)*(RD_IREF=B$6)*(RD_RB=$B$38)*(RD_PASS=1))>0,"≥"&TEXT($B$38/1000,"General")&" kΩ (扫描上限)",TEXT(LOOKUP(2,1/((RD_VBP=$A11)*(RD_IREF=B$6)*(RD_PASS=1)),RD_RB)/1000,"General")&" kΩ")) -> 1199.551 kΩ | C11: =IF(SUMPRODUCT((RD_VBP=$A11)*(RD_IREF=C$6)*(RD_PASS=1))=0,"N/A (基础误差>1.5%)",IF(SUMPRODUCT((RD_VBP=$A11)*(RD_IREF=C$6)*(RD_RB=$B$38)*(RD_PASS=1))>0,"≥"&TEXT($B$38/1000,"General")&" kΩ (扫描上限)",TEXT(LOOKUP(2,1/((RD_VBP=$A11)*(RD_IREF=C$6)*(RD_PASS=1)),RD_RB)/1000,"General")&" kΩ")) -> 606.083 kΩ | D11: =IF(SUMPRODUCT((RD_VBP=$A11)*(RD_IREF=D$6)*(RD_PASS=1))=0,"N/A (基础误差>1.5%)",IF(SUMPRODUCT((RD_VBP=$A11)*(RD_IREF=D$6)*(RD_RB=$B$38)*(RD_PASS=1))>0,"≥"&TEXT($B$38/1000,"General")&" kΩ (扫描上限)",TEXT(LOOKUP(2,1/((RD_VBP=$A11)*(RD_IREF=D$6)*(RD_PASS=1)),RD_RB)/1000,"General")&" kΩ")) -> 240.631 kΩ | E11: =IF(SUMPRODUCT((RD_VBP=$A11)*(RD_IREF=E$6)*(RD_PASS=1))=0,"N/A (基础误差>1.5%)",IF(SUMPRODUCT((RD_VBP=$A11)*(RD_IREF=E$6)*(RD_RB=$B$38)*(RD_PASS=1))>0,"≥"&TEXT($B$38/1000,"General")&" kΩ (扫描上限)",TEXT(LOOKUP(2,1/((RD_VBP=$A11)*(RD_IREF=E$6)*(RD_PASS=1)),RD_RB)/1000,"General")&" kΩ")) -> 118.814 kΩ | F11: =IF(SUMPRODUCT((RD_VBP=$A11)*(RD_IREF=F$6)*(RD_PASS=1))=0,"N/A (基础误差>1.5%)",IF(SUMPRODUCT((RD_VBP=$A11)*(RD_IREF=F$6)*(RD_RB=$B$38)*(RD_PASS=1))>0,"≥"&TEXT($B$38/1000,"General")&" kΩ (扫描上限)",TEXT(LOOKUP(2,1/((RD_VBP=$A11)*(RD_IREF=F$6)*(RD_PASS=1)),RD_RB)/1000,"General")&" kΩ")) -> 57.904 kΩ
A12: 15 | B12: =IF(SUMPRODUCT((RD_VBP=$A12)*(RD_IREF=B$6)*(RD_PASS=1))=0,"N/A (基础误差>1.5%)",IF(SUMPRODUCT((RD_VBP=$A12)*(RD_IREF=B$6)*(RD_RB=$B$38)*(RD_PASS=1))>0,"≥"&TEXT($B$38/1000,"General")&" kΩ (扫描上限)",TEXT(LOOKUP(2,1/((RD_VBP=$A12)*(RD_IREF=B$6)*(RD_PASS=1)),RD_RB)/1000,"General")&" kΩ")) -> 1503.637 kΩ | C12: =IF(SUMPRODUCT((RD_VBP=$A12)*(RD_IREF=C$6)*(RD_PASS=1))=0,"N/A (基础误差>1.5%)",IF(SUMPRODUCT((RD_VBP=$A12)*(RD_IREF=C$6)*(RD_RB=$B$38)*(RD_PASS=1))>0,"≥"&TEXT($B$38/1000,"General")&" kΩ (扫描上限)",TEXT(LOOKUP(2,1/((RD_VBP=$A12)*(RD_IREF=C$6)*(RD_PASS=1)),RD_RB)/1000,"General")&" kΩ")) -> 758.366 kΩ | D12: =IF(SUMPRODUCT((RD_VBP=$A12)*(RD_IREF=D$6)*(RD_PASS=1))=0,"N/A (基础误差>1.5%)",IF(SUMPRODUCT((RD_VBP=$A12)*(RD_IREF=D$6)*(RD_RB=$B$38)*(RD_PASS=1))>0,"≥"&TEXT($B$38/1000,"General")&" kΩ (扫描上限)",TEXT(LOOKUP(2,1/((RD_VBP=$A12)*(RD_IREF=D$6)*(RD_PASS=1)),RD_RB)/1000,"General")&" kΩ")) -> 301.545 kΩ | E12: =IF(SUMPRODUCT((RD_VBP=$A12)*(RD_IREF=E$6)*(RD_PASS=1))=0,"N/A (基础误差>1.5%)",IF(SUMPRODUCT((RD_VBP=$A12)*(RD_IREF=E$6)*(RD_RB=$B$38)*(RD_PASS=1))>0,"≥"&TEXT($B$38/1000,"General")&" kΩ (扫描上限)",TEXT(LOOKUP(2,1/((RD_VBP=$A12)*(RD_IREF=E$6)*(RD_PASS=1)),RD_RB)/1000,"General")&" kΩ")) -> 149.271 kΩ | F12: =IF(SUMPRODUCT((RD_VBP=$A12)*(RD_IREF=F$6)*(RD_PASS=1))=0,"N/A (基础误差>1.5%)",IF(SUMPRODUCT((RD_VBP=$A12)*(RD_IREF=F$6)*(RD_RB=$B$38)*(RD_PASS=1))>0,"≥"&TEXT($B$38/1000,"General")&" kΩ (扫描上限)",TEXT(LOOKUP(2,1/((RD_VBP=$A12)*(RD_IREF=F$6)*(RD_PASS=1)),RD_RB)/1000,"General")&" kΩ")) -> 73.133 kΩ
A13: 图例 / Legend：
A14: 精确值（如 163 kΩ） | B14: RB 继续增大即 FAIL，属真实临界值
A15: ≥200 kΩ (扫描上限) | B15: 在扫描上限 10000 kΩ 处仍 PASS → 结果是【下限】，真实 Rmax 更大，需扩大扫描范围
A16: N/A (基础误差>1.5%) | B16: 最小负载 RB=10 kΩ 时 IERR 已 >1.5% → 属电路基础恒流误差，【不能】解释为 Rmax = 0；原始数据保留于 Raw_Data
A18: B. Rmax 热力图数据 (kΩ) — 仅含【实测精确值】；空白 = 本次扫描未覆盖（≥扫描上限 或 N/A）。本块用于条件格式热力图与 Charts 工作表。
A19: BONE_P / V | B19: 10 | C19: 20 | D19: 50 | E19: 100 | F19: 200
A20: 3.3 | B20: 317.808 | C20: 164.462 | D20: 63.982 | E20: 30.489 | F20: 13.742
A21: 5 | B21: 490.087 | C21: 250.755 | D21: 98.499 | E21: 47.748 | F21: 22.371
A22: 8 | B22: 794.129 | C22: 403.038 | D22: 159.413 | E22: 78.205 | F22: 37.6
A23: 10 | B23: 996.836 | C23: 504.56 | D23: 200.022 | E23: 98.509 | F23: 47.752
A24: 12 | B24: 1199.551 | C24: 606.083 | D24: 240.631 | E24: 118.814 | F24: 57.904
A25: 15 | B25: 1503.637 | C25: 758.366 | D25: 301.545 | E25: 149.271 | F25: 73.133
A27: C. 数据状态矩阵 — 绿 = 精确临界值 ；黄 = ≥扫描上限（下限，需扩大扫描）；红 = N/A（基础误差>1.5%）
A28: BONE_P / V | B28: 10 | C28: 20 | D28: 50 | E28: 100 | F28: 200
A29: 3.3 | B29: 精确 | C29: 精确 | D29: 精确 | E29: 精确 | F29: 精确
A30: 5 | B30: 精确 | C30: 精确 | D30: 精确 | E30: 精确 | F30: 精确
A31: 8 | B31: 精确 | C31: 精确 | D31: 精确 | E31: 精确 | F31: 精确
A32: 10 | B32: 精确 | C32: 精确 | D32: 精确 | E32: 精确 | F32: 精确
A33: 12 | B33: 精确 | C33: 精确 | D33: 精确 | E33: 精确 | F33: 精确
A34: 15 | B34: 精确 | C34: 精确 | D34: 精确 | E34: 精确 | F34: 精确
A36: D. 全局参数（供本工作簿各处公式引用）
A37: 扫描最小 RB (Ω) | B37: =MIN(Raw_Data!$D$2:$D$20001) -> 10000
A38: 扫描最大 RB (Ω) | B38: =MAX(Raw_Data!$D$2:$D$20001) -> 10000000
A39: 数据行数 (仿真组合数) | B39: =COUNT(Raw_Data!$D$2:$D$20001) -> 12369
A40: PASS 判据 IERR ≤ (%) | B40: 1.5
A41: VBP 取值个数 | B41: =COUNT($A$7:$A$12) -> 6
A42: 目标电流取值个数 | B42: =COUNT($B$6:$F$6) -> 5
A43: 扫描上限处仍 PASS 的组合数 (→下限) | B43: =SUMPRODUCT((Raw_Data!$D$2:$D$20001=$B$38)*(Raw_Data!$I$2:$I$20001=1)) -> 0
A44: 最小负载即 FAIL 的组合数 (→N/A) | B44: =SUMPRODUCT((Raw_Data!$D$2:$D$20001=$B$37)*(Raw_Data!$I$2:$I$20001=0)) -> 0
...

Sheet Boundary_Detail
A1: Boundary_Detail — 每个 BONE_P × 目标电流的恒流临界区间
A2: Last_PASS_RB = 仍满足 PASS=1 的最大 RB ；First_FAIL_RB = 其上方第一个 PASS=0 的 RB。二者之间即建议细扫窗口（当前分辨率 1 kΩ）。
A4: VBP_V | B4: IREF_uA | C4: Last_PASS_RB_kOhm | D4: First_FAIL_RB_kOhm | E4: Last_PASS_I_uA | F4: First_FAIL_I_uA | G4: Last_PASS_Error_pct | H4: First_FAIL_Error_pct | I4: Refine_Window_kOhm | J4: Status_Note | K4: （参考）Last_PASS_RB_Ohm | L4: （参考）First_FAIL_RB_Ohm
A5: 3.3 | B5: 10 | C5: =IF($K5="","N/A",$K5/1000) -> 317.808 | D5: =IF($K5="","N/A (无临界区)",IF($L5="","无 (扫描上限内仍 PASS)",$L5/1000)) -> 317.809 | E5: =IF($K5="","N/A",LOOKUP(2,1/((RD_VBP=$A5)*(RD_IREF=$B5)*(RD_RB=$K5)),RD_IB)) -> 9.85 | F5: =IF($L5="","N/A",LOOKUP(2,1/((RD_VBP=$A5)*(RD_IREF=$B5)*(RD_RB=$L5)),RD_IB)) -> 9.85 | G5: =IF($K5="","N/A",LOOKUP(2,1/((RD_VBP=$A5)*(RD_IREF=$B5)*(RD_RB=$K5)),RD_IERR)) -> 1.4999992 | H5: =IF($L5="","N/A",LOOKUP(2,1/((RD_VBP=$A5)*(RD_IREF=$B5)*(RD_RB=$L5)),RD_IERR)) -> 1.500004 | I5: =IF($K5="","— (需先解决基础误差)",IF($L5="","— (需将扫描上限扩大到 "&TEXT(10000,"General")&" kΩ 以上)",TEXT($K5/1000,"General")&" ~ "&TEXT($L5/1000,"General")&" kΩ 之间细扫")) -> 317.808 ~ 317.809 kΩ 之间细扫 | J5: =IF(SUMPRODUCT((RD_VBP=$A5)*(RD_IREF=$B5)*(RD_PASS=1))=0,"基础误差>1.5%：全程 FAIL（最小负载 RB="&TEXT(Rmax_Summary!$B$37/1000,"General")&" kΩ 时 IERR 已 >1.5%），无恒流临界区，应改进电路而非缩小负载",IF($L5="","扫描上限 ("&TEXT(Rmax_Summary!$B$38/1000,"General")&" kΩ) 内仍 PASS：Rmax 为下限，需扩大扫描范围","正常恒流临界区，建议按 I 列窗口细扫")) -> 正常恒流临界区，建议按 I 列窗口细扫 | K5: =IFERROR(LOOKUP(2,1/((RD_VBP=$A5)*(RD_IREF=$B5)*(RD_PASS=1)),RD_RB),"") -> 317808 | L5: =IF($K5="","",IF(SUMPRODUCT((RD_VBP=$A5)*(RD_IREF=$B5)*(RD_PASS=0)*(RD_RB>$K5))=0,"",SUMPRODUCT(MIN((RD_VBP=$A5)*(RD_IREF=$B5)*(RD_PASS=0)*(RD_RB>$K5)*RD_RB+(1-(RD_VBP=$A5)*(RD_IREF=$B5)*(RD_PASS=0)*(RD_RB>$K5))*1000000000000000)))) -> 317809
A6: 3.3 | B6: 20 | C6: =IF($K6="","N/A",$K6/1000) -> 164.462 | D6: =IF($K6="","N/A (无临界区)",IF($L6="","无 (扫描上限内仍 PASS)",$L6/1000)) -> 164.463 | E6: =IF($K6="","N/A",LOOKUP(2,1/((RD_VBP=$A6)*(RD_IREF=$B6)*(RD_RB=$K6)),RD_IB)) -> 19.70002 | F6: =IF($L6="","N/A",LOOKUP(2,1/((RD_VBP=$A6)*(RD_IREF=$B6)*(RD_RB=$L6)),RD_IB)) -> 19.699904 | G6: =IF($K6="","N/A",LOOKUP(2,1/((RD_VBP=$A6)*(RD_IREF=$B6)*(RD_RB=$K6)),RD_IERR)) -> 1.4999007 | H6: =IF($L6="","N/A",LOOKUP(2,1/((RD_VBP=$A6)*(RD_IREF=$B6)*(RD_RB=$L6)),RD_IERR)) -> 1.5004785 | I6: =IF($K6="","— (需先解决基础误差)",IF($L6="","— (需将扫描上限扩大到 "&TEXT(10000,"General")&" kΩ 以上)",TEXT($K6/1000,"General")&" ~ "&TEXT($L6/1000,"General")&" kΩ 之间细扫")) -> 164.462 ~ 164.463 kΩ 之间细扫 | J6: =IF(SUMPRODUCT((RD_VBP=$A6)*(RD_IREF=$B6)*(RD_PASS=1))=0,"基础误差>1.5%：全程 FAIL（最小负载 RB="&TEXT(Rmax_Summary!$B$37/1000,"General")&" kΩ 时 IERR 已 >1.5%），无恒流临界区，应改进电路而非缩小负载",IF($L6="","扫描上限 ("&TEXT(Rmax_Summary!$B$38/1000,"General")&" kΩ) 内仍 PASS：Rmax 为下限，需扩大扫描范围","正常恒流临界区，建议按 I 列窗口细扫")) -> 正常恒流临界区，建议按 I 列窗口细扫 | K6: =IFERROR(LOOKUP(2,1/((RD_VBP=$A6)*(RD_IREF=$B6)*(RD_PASS=1)),RD_RB),"") -> 164462 | L6: =IF($K6="","",IF(SUMPRODUCT((RD_VBP=$A6)*(RD_IREF=$B6)*(RD_PASS=0)*(RD_RB>$K6))=0,"",SUMPRODUCT(MIN((RD_VBP=$A6)*(RD_IREF=$B6)*(RD_PASS=0)*(RD_RB>$K6)*RD_RB+(1-(RD_VBP=$A6)*(RD_IREF=$B6)*(RD_PASS=0)*(RD_RB>$K6))*1000000000000000)))) -> 164463
A7: 3.3 | B7: 50 | C7: =IF($K7="","N/A",$K7/1000) -> 63.982 | D7: =IF($K7="","N/A (无临界区)",IF($L7="","无 (扫描上限内仍 PASS)",$L7/1000)) -> 63.983 | E7: =IF($K7="","N/A",LOOKUP(2,1/((RD_VBP=$A7)*(RD_IREF=$B7)*(RD_RB=$K7)),RD_IB)) -> 49.250097 | F7: =IF($L7="","N/A",LOOKUP(2,1/((RD_VBP=$A7)*(RD_IREF=$B7)*(RD_RB=$L7)),RD_IB)) -> 49.249362 | G7: =IF($K7="","N/A",LOOKUP(2,1/((RD_VBP=$A7)*(RD_IREF=$B7)*(RD_RB=$K7)),RD_IERR)) -> 1.4998066 | H7: =IF($L7="","N/A",LOOKUP(2,1/((RD_VBP=$A7)*(RD_IREF=$B7)*(RD_RB=$L7)),RD_IERR)) -> 1.5012763 | I7: =IF($K7="","— (需先解决基础误差)",IF($L7="","— (需将扫描上限扩大到 "&TEXT(10000,"General")&" kΩ 以上)",TEXT($K7/1000,"General")&" ~ "&TEXT($L7/1000,"General")&" kΩ 之间细扫")) -> 63.982 ~ 63.983 kΩ 之间细扫 | J7: =IF(SUMPRODUCT((RD_VBP=$A7)*(RD_IREF=$B7)*(RD_PASS=1))=0,"基础误差>1.5%：全程 FAIL（最小负载 RB="&TEXT(Rmax_Summary!$B$37/1000,"General")&" kΩ 时 IERR 已 >1.5%），无恒流临界区，应改进电路而非缩小负载",IF($L7="","扫描上限 ("&TEXT(Rmax_Summary!$B$38/1000,"General")&" kΩ) 内仍 PASS：Rmax 为下限，需扩大扫描范围","正常恒流临界区，建议按 I 列窗口细扫")) -> 正常恒流临界区，建议按 I 列窗口细扫 | K7: =IFERROR(LOOKUP(2,1/((RD_VBP=$A7)*(RD_IREF=$B7)*(RD_PASS=1)),RD_RB),"") -> 63982 | L7: =IF($K7="","",IF(SUMPRODUCT((RD_VBP=$A7)*(RD_IREF=$B7)*(RD_PASS=0)*(RD_RB>$K7))=0,"",SUMPRODUCT(MIN((RD_VBP=$A7)*(RD_IREF=$B7)*(RD_PASS=0)*(RD_RB>$K7)*RD_RB+(1-(RD_VBP=$A7)*(RD_IREF=$B7)*(RD_PASS=0)*(RD_RB>$K7))*1000000000000000)))) -> 63983
A8: 3.3 | B8: 100 | C8: =IF($K8="","N/A",$K8/1000) -> 30.489 | D8: =IF($K8="","N/A (无临界区)",IF($L8="","无 (扫描上限内仍 PASS)",$L8/1000)) -> 30.49 | E8: =IF($K8="","N/A",LOOKUP(2,1/((RD_VBP=$A8)*(RD_IREF=$B8)*(RD_RB=$K8)),RD_IB)) -> 98.500965 | F8: =IF($L8="","N/A",LOOKUP(2,1/((RD_VBP=$A8)*(RD_IREF=$B8)*(RD_RB=$L8)),RD_IB)) -> 98.498025 | G8: =IF($K8="","N/A",LOOKUP(2,1/((RD_VBP=$A8)*(RD_IREF=$B8)*(RD_RB=$K8)),RD_IERR)) -> 1.4990353 | H8: =IF($L8="","N/A",LOOKUP(2,1/((RD_VBP=$A8)*(RD_IREF=$B8)*(RD_RB=$L8)),RD_IERR)) -> 1.5019748 | I8: =IF($K8="","— (需先解决基础误差)",IF($L8="","— (需将扫描上限扩大到 "&TEXT(10000,"General")&" kΩ 以上)",TEXT($K8/1000,"General")&" ~ "&TEXT($L8/1000,"General")&" kΩ 之间细扫")) -> 30.489 ~ 30.49 kΩ 之间细扫 | J8: =IF(SUMPRODUCT((RD_VBP=$A8)*(RD_IREF=$B8)*(RD_PASS=1))=0,"基础误差>1.5%：全程 FAIL（最小负载 RB="&TEXT(Rmax_Summary!$B$37/1000,"General")&" kΩ 时 IERR 已 >1.5%），无恒流临界区，应改进电路而非缩小负载",IF($L8="","扫描上限 ("&TEXT(Rmax_Summary!$B$38/1000,"General")&" kΩ) 内仍 PASS：Rmax 为下限，需扩大扫描范围","正常恒流临界区，建议按 I 列窗口细扫")) -> 正常恒流临界区，建议按 I 列窗口细扫 | K8: =IFERROR(LOOKUP(2,1/((RD_VBP=$A8)*(RD_IREF=$B8)*(RD_PASS=1)),RD_RB),"") -> 30489 | L8: =IF($K8="","",IF(SUMPRODUCT((RD_VBP=$A8)*(RD_IREF=$B8)*(RD_PASS=0)*(RD_RB>$K8))=0,"",SUMPRODUCT(MIN((RD_VBP=$A8)*(RD_IREF=$B8)*(RD_PASS=0)*(RD_RB>$K8)*RD_RB+(1-(RD_VBP=$A8)*(RD_IREF=$B8)*(RD_PASS=0)*(RD_RB>$K8))*1000000000000000)))) -> 30490
A9: 3.3 | B9: 200 | C9: =IF($K9="","N/A",$K9/1000) -> 13.742 | D9: =IF($K9="","N/A (无临界区)",IF($L9="","无 (扫描上限内仍 PASS)",$L9/1000)) -> 13.743 | E9: =IF($K9="","N/A",LOOKUP(2,1/((RD_VBP=$A9)*(RD_IREF=$B9)*(RD_RB=$K9)),RD_IB)) -> 197.00213 | F9: =IF($L9="","N/A",LOOKUP(2,1/((RD_VBP=$A9)*(RD_IREF=$B9)*(RD_RB=$L9)),RD_IB)) -> 196.99036 | G9: =IF($K9="","N/A",LOOKUP(2,1/((RD_VBP=$A9)*(RD_IREF=$B9)*(RD_RB=$K9)),RD_IERR)) -> 1.4989371 | H9: =IF($L9="","N/A",LOOKUP(2,1/((RD_VBP=$A9)*(RD_IREF=$B9)*(RD_RB=$L9)),RD_IERR)) -> 1.5048197 | I9: =IF($K9="","— (需先解决基础误差)",IF($L9="","— (需将扫描上限扩大到 "&TEXT(10000,"General")&" kΩ 以上)",TEXT($K9/1000,"General")&" ~ "&TEXT($L9/1000,"General")&" kΩ 之间细扫")) -> 13.742 ~ 13.743 kΩ 之间细扫 | J9: =IF(SUMPRODUCT((RD_VBP=$A9)*(RD_IREF=$B9)*(RD_PASS=1))=0,"基础误差>1.5%：全程 FAIL（最小负载 RB="&TEXT(Rmax_Summary!$B$37/1000,"General")&" kΩ 时 IERR 已 >1.5%），无恒流临界区，应改进电路而非缩小负载",IF($L9="","扫描上限 ("&TEXT(Rmax_Summary!$B$38/1000,"General")&" kΩ) 内仍 PASS：Rmax 为下限，需扩大扫描范围","正常恒流临界区，建议按 I 列窗口细扫")) -> 正常恒流临界区，建议按 I 列窗口细扫 | K9: =IFERROR(LOOKUP(2,1/((RD_VBP=$A9)*(RD_IREF=$B9)*(RD_PASS=1)),RD_RB),"") -> 13742 | L9: =IF($K9="","",IF(SUMPRODUCT((RD_VBP=$A9)*(RD_IREF=$B9)*(RD_PASS=0)*(RD_RB>$K9))=0,"",SUMPRODUCT(MIN((RD_VBP=$A9)*(RD_IREF=$B9)*(RD_PASS=0)*(RD_RB>$K9)*RD_RB+(1-(RD_VBP=$A9)*(RD_IREF=$B9)*(RD_PASS=0)*(RD_RB>$K9))*1000000000000000)))) -> 13743
A10: 5 | B10: 10 | C10: =IF($K10="","N/A",$K10/1000) -> 490.087 | D10: =IF($K10="","N/A (无临界区)",IF($L10="","无 (扫描上限内仍 PASS)",$L10/1000)) -> 490.088 | E10: =IF($K10="","N/A",LOOKUP(2,1/((RD_VBP=$A10)*(RD_IREF=$B10)*(RD_RB=$K10)),RD_IB)) -> 9.85 | F10: =IF($L10="","N/A",LOOKUP(2,1/((RD_VBP=$A10)*(RD_IREF=$B10)*(RD_RB=$L10)),RD_IB)) -> 9.85 | G10: =IF($K10="","N/A",LOOKUP(2,1/((RD_VBP=$A10)*(RD_IREF=$B10)*(RD_RB=$K10)),RD_IERR)) -> 1.4999966 | H10: =IF($L10="","N/A",LOOKUP(2,1/((RD_VBP=$A10)*(RD_IREF=$B10)*(RD_RB=$L10)),RD_IERR)) -> 1.5000002 | I10: =IF($K10="","— (需先解决基础误差)",IF($L10="","— (需将扫描上限扩大到 "&TEXT(10000,"General")&" kΩ 以上)",TEXT($K10/1000,"General")&" ~ "&TEXT($L10/1000,"General")&" kΩ 之间细扫")) -> 490.087 ~ 490.088 kΩ 之间细扫 | J10: =IF(SUMPRODUCT((RD_VBP=$A10)*(RD_IREF=$B10)*(RD_PASS=1))=0,"基础误差>1.5%：全程 FAIL（最小负载 RB="&TEXT(Rmax_Summary!$B$37/1000,"General")&" kΩ 时 IERR 已 >1.5%），无恒流临界区，应改进电路而非缩小负载",IF($L10="","扫描上限 ("&TEXT(Rmax_Summary!$B$38/1000,"General")&" kΩ) 内仍 PASS：Rmax 为下限，需扩大扫描范围","正常恒流临界区，建议按 I 列窗口细扫")) -> 正常恒流临界区，建议按 I 列窗口细扫 | K10: =IFERROR(LOOKUP(2,1/((RD_VBP=$A10)*(RD_IREF=$B10)*(RD_PASS=1)),RD_RB),"") -> 490087 | L10: =IF($K10="","",IF(SUMPRODUCT((RD_VBP=$A10)*(RD_IREF=$B10)*(RD_PASS=0)*(RD_RB>$K10))=0,"",SUMPRODUCT(MIN((RD_VBP=$A10)*(RD_IREF=$B10)*(RD_PASS=0)*(RD_RB>$K10)*RD_RB+(1-(RD_VBP=$A10)*(RD_IREF=$B10)*(RD_PASS=0)*(RD_RB>$K10))*1000000000000000)))) -> 490088
A11: 5 | B11: 20 | C11: =IF($K11="","N/A",$K11/1000) -> 250.755 | D11: =IF($K11="","N/A (无临界区)",IF($L11="","无 (扫描上限内仍 PASS)",$L11/1000)) -> 250.756 | E11: =IF($K11="","N/A",LOOKUP(2,1/((RD_VBP=$A11)*(RD_IREF=$B11)*(RD_RB=$K11)),RD_IB)) -> 19.700052 | F11: =IF($L11="","N/A",LOOKUP(2,1/((RD_VBP=$A11)*(RD_IREF=$B11)*(RD_RB=$L11)),RD_IB)) -> 19.699976 | G11: =IF($K11="","N/A",LOOKUP(2,1/((RD_VBP=$A11)*(RD_IREF=$B11)*(RD_RB=$K11)),RD_IERR)) -> 1.4997387 | H11: =IF($L11="","N/A",LOOKUP(2,1/((RD_VBP=$A11)*(RD_IREF=$B11)*(RD_RB=$L11)),RD_IERR)) -> 1.5001206 | I11: =IF($K11="","— (需先解决基础误差)",IF($L11="","— (需将扫描上限扩大到 "&TEXT(10000,"General")&" kΩ 以上)",TEXT($K11/1000,"General")&" ~ "&TEXT($L11/1000,"General")&" kΩ 之间细扫")) -> 250.755 ~ 250.756 kΩ 之间细扫 | J11: =IF(SUMPRODUCT((RD_VBP=$A11)*(RD_IREF=$B11)*(RD_PASS=1))=0,"基础误差>1.5%：全程 FAIL（最小负载 RB="&TEXT(Rmax_Summary!$B$37/1000,"General")&" kΩ 时 IERR 已 >1.5%），无恒流临界区，应改进电路而非缩小负载",IF($L11="","扫描上限 ("&TEXT(Rmax_Summary!$B$38/1000,"General")&" kΩ) 内仍 PASS：Rmax 为下限，需扩大扫描范围","正常恒流临界区，建议按 I 列窗口细扫")) -> 正常恒流临界区，建议按 I 列窗口细扫 | K11: =IFERROR(LOOKUP(2,1/((RD_VBP=$A11)*(RD_IREF=$B11)*(RD_PASS=1)),RD_RB),"") -> 250755 | L11: =IF($K11="","",IF(SUMPRODUCT((RD_VBP=$A11)*(RD_IREF=$B11)*(RD_PASS=0)*(RD_RB>$K11))=0,"",SUMPRODUCT(MIN((RD_VBP=$A11)*(RD_IREF=$B11)*(RD_PASS=0)*(RD_RB>$K11)*RD_RB+(1-(RD_VBP=$A11)*(RD_IREF=$B11)*(RD_PASS=0)*(RD_RB>$K11))*1000000000000000)))) -> 250756
A12: 5 | B12: 50 | C12: =IF($K12="","N/A",$K12/1000) -> 98.499 | D12: =IF($K12="","N/A (无临界区)",IF($L12="","无 (扫描上限内仍 PASS)",$L12/1000)) -> 98.5 | E12: =IF($K12="","N/A",LOOKUP(2,1/((RD_VBP=$A12)*(RD_IREF=$B12)*(RD_RB=$K12)),RD_IB)) -> 49.250437 | F12: =IF($L12="","N/A",LOOKUP(2,1/((RD_VBP=$A12)*(RD_IREF=$B12)*(RD_RB=$L12)),RD_IB)) -> 49.249949 | G12: =IF($K12="","N/A",LOOKUP(2,1/((RD_VBP=$A12)*(RD_IREF=$B12)*(RD_RB=$K12)),RD_IERR)) -> 1.4991263 | H12: =IF($L12="","N/A",LOOKUP(2,1/((RD_VBP=$A12)*(RD_IREF=$B12)*(RD_RB=$L12)),RD_IERR)) -> 1.5001013 | I12: =IF($K12="","— (需先解决基础误差)",IF($L12="","— (需将扫描上限扩大到 "&TEXT(10000,"General")&" kΩ 以上)",TEXT($K12/1000,"General")&" ~ "&TEXT($L12/1000,"General")&" kΩ 之间细扫")) -> 98.499 ~ 98.5 kΩ 之间细扫 | J12: =IF(SUMPRODUCT((RD_VBP=$A12)*(RD_IREF=$B12)*(RD_PASS=1))=0,"基础误差>1.5%：全程 FAIL（最小负载 RB="&TEXT(Rmax_Summary!$B$37/1000,"General")&" kΩ 时 IERR 已 >1.5%），无恒流临界区，应改进电路而非缩小负载",IF($L12="","扫描上限 ("&TEXT(Rmax_Summary!$B$38/1000,"General")&" kΩ) 内仍 PASS：Rmax 为下限，需扩大扫描范围","正常恒流临界区，建议按 I 列窗口细扫")) -> 正常恒流临界区，建议按 I 列窗口细扫 | K12: =IFERROR(LOOKUP(2,1/((RD_VBP=$A12)*(RD_IREF=$B12)*(RD_PASS=1)),RD_RB),"") -> 98499 | L12: =IF($K12="","",IF(SUMPRODUCT((RD_VBP=$A12)*(RD_IREF=$B12)*(RD_PASS=0)*(RD_RB>$K12))=0,"",SUMPRODUCT(MIN((RD_VBP=$A12)*(RD_IREF=$B12)*(RD_PASS=0)*(RD_RB>$K12)*RD_RB+(1-(RD_VBP=$A12)*(RD_IREF=$B12)*(RD_PASS=0)*(RD_RB>$K12))*1000000000000000)))) -> 98500
A13: 5 | B13: 100 | C13: =IF($K13="","N/A",$K13/1000) -> 47.748 | D13: =IF($K13="","N/A (无临界区)",IF($L13="","无 (扫描上限内仍 PASS)",$L13/1000)) -> 47.749 | E13: =IF($K13="","N/A",LOOKUP(2,1/((RD_VBP=$A13)*(RD_IREF=$B13)*(RD_RB=$K13)),RD_IB)) -> 98.500412 | F13: =IF($L13="","N/A",LOOKUP(2,1/((RD_VBP=$A13)*(RD_IREF=$B13)*(RD_RB=$L13)),RD_IB)) -> 98.498469 | G13: =IF($K13="","N/A",LOOKUP(2,1/((RD_VBP=$A13)*(RD_IREF=$B13)*(RD_RB=$K13)),RD_IERR)) -> 1.4995883 | H13: =IF($L13="","N/A",LOOKUP(2,1/((RD_VBP=$A13)*(RD_IREF=$B13)*(RD_RB=$L13)),RD_IERR)) -> 1.501531 | I13: =IF($K13="","— (需先解决基础误差)",IF($L13="","— (需将扫描上限扩大到 "&TEXT(10000,"General")&" kΩ 以上)",TEXT($K13/1000,"General")&" ~ "&TEXT($L13/1000,"General")&" kΩ 之间细扫")) -> 47.748 ~ 47.749 kΩ 之间细扫 | J13: =IF(SUMPRODUCT((RD_VBP=$A13)*(RD_IREF=$B13)*(RD_PASS=1))=0,"基础误差>1.5%：全程 FAIL（最小负载 RB="&TEXT(Rmax_Summary!$B$37/1000,"General")&" kΩ 时 IERR 已 >1.5%），无恒流临界区，应改进电路而非缩小负载",IF($L13="","扫描上限 ("&TEXT(Rmax_Summary!$B$38/1000,"General")&" kΩ) 内仍 PASS：Rmax 为下限，需扩大扫描范围","正常恒流临界区，建议按 I 列窗口细扫")) -> 正常恒流临界区，建议按 I 列窗口细扫 | K13: =IFERROR(LOOKUP(2,1/((RD_VBP=$A13)*(RD_IREF=$B13)*(RD_PASS=1)),RD_RB),"") -> 47748 | L13: =IF($K13="","",IF(SUMPRODUCT((RD_VBP=$A13)*(RD_IREF=$B13)*(RD_PASS=0)*(RD_RB>$K13))=0,"",SUMPRODUCT(MIN((RD_VBP=$A13)*(RD_IREF=$B13)*(RD_PASS=0)*(RD_RB>$K13)*RD_RB+(1-(RD_VBP=$A13)*(RD_IREF=$B13)*(RD_PASS=0)*(RD_RB>$K13))*1000000000000000)))) -> 47749
A14: 5 | B14: 200 | C14: =IF($K14="","N/A",$K14/1000) -> 22.371 | D14: =IF($K14="","N/A (无临界区)",IF($L14="","无 (扫描上限内仍 PASS)",$L14/1000)) -> 22.372 | E14: =IF($K14="","N/A",LOOKUP(2,1/((RD_VBP=$A14)*(RD_IREF=$B14)*(RD_RB=$K14)),RD_IB)) -> 197.00483 | F14: =IF($L14="","N/A",LOOKUP(2,1/((RD_VBP=$A14)*(RD_IREF=$B14)*(RD_RB=$L14)),RD_IB)) -> 196.99707 | G14: =IF($K14="","N/A",LOOKUP(2,1/((RD_VBP=$A14)*(RD_IREF=$B14)*(RD_RB=$K14)),RD_IERR)) -> 1.4975838 | H14: =IF($L14="","N/A",LOOKUP(2,1/((RD_VBP=$A14)*(RD_IREF=$B14)*(RD_RB=$L14)),RD_IERR)) -> 1.5014655 | I14: =IF($K14="","— (需先解决基础误差)",IF($L14="","— (需将扫描上限扩大到 "&TEXT(10000,"General")&" kΩ 以上)",TEXT($K14/1000,"General")&" ~ "&TEXT($L14/1000,"General")&" kΩ 之间细扫")) -> 22.371 ~ 22.372 kΩ 之间细扫 | J14: =IF(SUMPRODUCT((RD_VBP=$A14)*(RD_IREF=$B14)*(RD_PASS=1))=0,"基础误差>1.5%：全程 FAIL（最小负载 RB="&TEXT(Rmax_Summary!$B$37/1000,"General")&" kΩ 时 IERR 已 >1.5%），无恒流临界区，应改进电路而非缩小负载",IF($L14="","扫描上限 ("&TEXT(Rmax_Summary!$B$38/1000,"General")&" kΩ) 内仍 PASS：Rmax 为下限，需扩大扫描范围","正常恒流临界区，建议按 I 列窗口细扫")) -> 正常恒流临界区，建议按 I 列窗口细扫 | K14: =IFERROR(LOOKUP(2,1/((RD_VBP=$A14)*(RD_IREF=$B14)*(RD_PASS=1)),RD_RB),"") -> 22371 | L14: =IF($K14="","",IF(SUMPRODUCT((RD_VBP=$A14)*(RD_IREF=$B14)*(RD_PASS=0)*(RD_RB>$K14))=0,"",SUMPRODUCT(MIN((RD_VBP=$A14)*(RD_IREF=$B14)*(RD_PASS=0)*(RD_RB>$K14)*RD_RB+(1-(RD_VBP=$A14)*(RD_IREF=$B14)*(RD_PASS=0)*(RD_RB>$K14))*1000000000000000)))) -> 22372
A15: 8 | B15: 10 | C15: =IF($K15="","N/A",$K15/1000) -> 794.129 | D15: =IF($K15="","N/A (无临界区)",IF($L15="","无 (扫描上限内仍 PASS)",$L15/1000)) -> 794.13 | E15: =IF($K15="","N/A",LOOKUP(2,1/((RD_VBP=$A15)*(RD_IREF=$B15)*(RD_RB=$K15)),RD_IB)) -> 9.85 | F15: =IF($L15="","N/A",LOOKUP(2,1/((RD_VBP=$A15)*(RD_IREF=$B15)*(RD_RB=$L15)),RD_IB)) -> 9.85 | G15: =IF($K15="","N/A",LOOKUP(2,1/((RD_VBP=$A15)*(RD_IREF=$B15)*(RD_RB=$K15)),RD_IERR)) -> 1.4999972 | H15: =IF($L15="","N/A",LOOKUP(2,1/((RD_VBP=$A15)*(RD_IREF=$B15)*(RD_RB=$L15)),RD_IERR)) -> 1.500001 | I15: =IF($K15="","— (需先解决基础误差)",IF($L15="","— (需将扫描上限扩大到 "&TEXT(10000,"General")&" kΩ 以上)",TEXT($K15/1000,"General")&" ~ "&TEXT($L15/1000,"General")&" kΩ 之间细扫")) -> 794.129 ~ 794.13 kΩ 之间细扫 | J15: =IF(SUMPRODUCT((RD_VBP=$A15)*(RD_IREF=$B15)*(RD_PASS=1))=0,"基础误差>1.5%：全程 FAIL（最小负载 RB="&TEXT(Rmax_Summary!$B$37/1000,"General")&" kΩ 时 IERR 已 >1.5%），无恒流临界区，应改进电路而非缩小负载",IF($L15="","扫描上限 ("&TEXT(Rmax_Summary!$B$38/1000,"General")&" kΩ) 内仍 PASS：Rmax 为下限，需扩大扫描范围","正常恒流临界区，建议按 I 列窗口细扫")) -> 正常恒流临界区，建议按 I 列窗口细扫 | K15: =IFERROR(LOOKUP(2,1/((RD_VBP=$A15)*(RD_IREF=$B15)*(RD_PASS=1)),RD_RB),"") -> 794129 | L15: =IF($K15="","",IF(SUMPRODUCT((RD_VBP=$A15)*(RD_IREF=$B15)*(RD_PASS=0)*(RD_RB>$K15))=0,"",SUMPRODUCT(MIN((RD_VBP=$A15)*(RD_IREF=$B15)*(RD_PASS=0)*(RD_RB>$K15)*RD_RB+(1-(RD_VBP=$A15)*(RD_IREF=$B15)*(RD_PASS=0)*(RD_RB>$K15))*1000000000000000)))) -> 794130
A16: 8 | B16: 20 | C16: =IF($K16="","N/A",$K16/1000) -> 403.038 | D16: =IF($K16="","N/A (无临界区)",IF($L16="","无 (扫描上限内仍 PASS)",$L16/1000)) -> 403.039 | E16: =IF($K16="","N/A",LOOKUP(2,1/((RD_VBP=$A16)*(RD_IREF=$B16)*(RD_RB=$K16)),RD_IB)) -> 19.700037 | F16: =IF($L16="","N/A",LOOKUP(2,1/((RD_VBP=$A16)*(RD_IREF=$B16)*(RD_RB=$L16)),RD_IB)) -> 19.699989 | G16: =IF($K16="","N/A",LOOKUP(2,1/((RD_VBP=$A16)*(RD_IREF=$B16)*(RD_RB=$K16)),RD_IERR)) -> 1.4998161 | H16: =IF($L16="","N/A",LOOKUP(2,1/((RD_VBP=$A16)*(RD_IREF=$B16)*(RD_RB=$L16)),RD_IERR)) -> 1.5000562 | I16: =IF($K16="","— (需先解决基础误差)",IF($L16="","— (需将扫描上限扩大到 "&TEXT(10000,"General")&" kΩ 以上)",TEXT($K16/1000,"General")&" ~ "&TEXT($L16/1000,"General")&" kΩ 之间细扫")) -> 403.038 ~ 403.039 kΩ 之间细扫 | J16: =IF(SUMPRODUCT((RD_VBP=$A16)*(RD_IREF=$B16)*(RD_PASS=1))=0,"基础误差>1.5%：全程 FAIL（最小负载 RB="&TEXT(Rmax_Summary!$B$37/1000,"General")&" kΩ 时 IERR 已 >1.5%），无恒流临界区，应改进电路而非缩小负载",IF($L16="","扫描上限 ("&TEXT(Rmax_Summary!$B$38/1000,"General")&" kΩ) 内仍 PASS：Rmax 为下限，需扩大扫描范围","正常恒流临界区，建议按 I 列窗口细扫")) -> 正常恒流临界区，建议按 I 列窗口细扫 | K16: =IFERROR(LOOKUP(2,1/((RD_VBP=$A16)*(RD_IREF=$B16)*(RD_PASS=1)),RD_RB),"") -> 403038 | L16: =IF($K16="","",IF(SUMPRODUCT((RD_VBP=$A16)*(RD_IREF=$B16)*(RD_PASS=0)*(RD_RB>$K16))=0,"",SUMPRODUCT(MIN((RD_VBP=$A16)*(RD_IREF=$B16)*(RD_PASS=0)*(RD_RB>$K16)*RD_RB+(1-(RD_VBP=$A16)*(RD_IREF=$B16)*(RD_PASS=0)*(RD_RB>$K16))*1000000000000000)))) -> 403039
... A34: 15 | B34: 200 | C34: =IF($K34="","N/A",$K34/1000) -> 73.133 | D34: =IF($K34="","N/A (无临界区)",IF($L34="","无 (扫描上限内仍 PASS)",$L34/1000)) -> 73.134 | E34: =IF($K34="","N/A",LOOKUP(2,1/((RD_VBP=$A34)*(RD_IREF=$B34)*(RD_RB=$K34)),RD_IB)) -> 197.00012 | F34: =IF($L34="","N/A",LOOKUP(2,1/((RD_VBP=$A34)*(RD_IREF=$B34)*(RD_RB=$L34)),RD_IB)) -> 196.99753 | G34: =IF($K34="","N/A",LOOKUP(2,1/((RD_VBP=$A34)*(RD_IREF=$B34)*(RD_RB=$K34)),RD_IERR)) -> 1.4999412 | H34: =IF($L34="","N/A",LOOKUP(2,1/((RD_VBP=$A34)*(RD_IREF=$B34)*(RD_RB=$L34)),RD_IERR)) -> 1.5012363 | I34: =IF($K34="","— (需先解决基础误差)",IF($L34="","— (需将扫描上限扩大到 "&TEXT(10000,"General")&" kΩ 以上)",TEXT($K34/1000,"General")&" ~ "&TEXT($L34/1000,"General")&" kΩ 之间细扫")) -> 73.133 ~ 73.134 kΩ 之间细扫 | J34: =IF(SUMPRODUCT((RD_VBP=$A34)*(RD_IREF=$B34)*(RD_PASS=1))=0,"基础误差>1.5%：全程 FAIL（最小负载 RB="&TEXT(Rmax_Summary!$B$37/1000,"General")&" kΩ 时 IERR 已 >1.5%），无恒流临界区，应改进电路而非缩小负载",IF($L34="","扫描上限 ("&TEXT(Rmax_Summary!$B$38/1000,"General")&" kΩ) 内仍 PASS：Rmax 为下限，需扩大扫描范围","正常恒流临界区，建议按 I 列窗口细扫")) -> 正常恒流临界区，建议按 I 列窗口细扫 | K34: =IFERROR(LOOKUP(2,1/((RD_VBP=$A34)*(RD_IREF=$B34)*(RD_PASS=1)),RD_RB),"") -> 73133 | L34: =IF($K34="","",IF(SUMPRODUCT((RD_VBP=$A34)*(RD_IREF=$B34)*(RD_PASS=0)*(RD_RB>$K34))=0,"",SUMPRODUCT(MIN((RD_VBP=$A34)*(RD_IREF=$B34)*(RD_PASS=0)*(RD_RB>$K34)*RD_RB+(1-(RD_VBP=$A34)*(RD_IREF=$B34)*(RD_PASS=0)*(RD_RB>$K34))*1000000000000000)))) -> 73134

Sheet Current_Accuracy
A1: Current_Accuracy — 目标恒流精度分析（IREF = 10 µA 全部数据保留，未因 PASS=0 删除）
A2: 低负载区域 = RB 取扫描最小值 10 kΩ（恒流区最有利工况）。误差直接取日志 .meas 的 IERR；另给出按公式重算值以便核对。
A4: A. 低负载工作点精度（每个 BONE_P × 目标电流一行；Last/Fail 临界详见 Boundary_Detail）
A5: VBP_V | B5: Target_I_uA | C5: RB_low_kOhm | D5: Actual_I_uA | E5: Error_pct | F5: Within_±1.5% | G5: V_BONE_V | H5: Error_recalc_pct | I5: Δ_vs_log_pctpt | J5: Note
A6: 3.3 | B6: 10 | C6: =Rmax_Summary!$B$37/1000 -> 10 | D6: =IFERROR(LOOKUP(2,1/((RD_VBP=$A6)*(RD_IREF=$B6)*(RD_RB=Rmax_Summary!$B$37)),RD_IB),"") -> 9.869797 | E6: =IFERROR(LOOKUP(2,1/((RD_VBP=$A6)*(RD_IREF=$B6)*(RD_RB=Rmax_Summary!$B$37)),RD_IERR),"") -> 1.3020312 | F6: =IF(NOT(ISNUMBER($E6)),"",IF($E6<=1.5,"Yes","No")) -> Yes | G6: =IFERROR(LOOKUP(2,1/((RD_VBP=$A6)*(RD_IREF=$B6)*(RD_RB=Rmax_Summary!$B$37)),RD_VB),"") -> 0.098697922 | H6: =IF(NOT(ISNUMBER($D6)),"",100*ABS($D6-$B6)/$B6) -> 1.30203 | I6: =IF(OR(NOT(ISNUMBER($E6)),NOT(ISNUMBER($H6))),"",$H6-$E6) -> -1.16e-06 | J6: =IF($F6="No","基础恒流误差 >1.5%：原始数据保留，Rmax_Summary 中标记为 N/A（不写作 0）",IF($F6="Yes","低负载区满足 ±1.5%","无数据")) -> 低负载区满足 ±1.5%
A7: 3.3 | B7: 20 | C7: =Rmax_Summary!$B$37/1000 -> 10 | D7: =IFERROR(LOOKUP(2,1/((RD_VBP=$A7)*(RD_IREF=$B7)*(RD_RB=Rmax_Summary!$B$37)),RD_IB),"") -> 19.849502 | E7: =IFERROR(LOOKUP(2,1/((RD_VBP=$A7)*(RD_IREF=$B7)*(RD_RB=Rmax_Summary!$B$37)),RD_IERR),"") -> 0.75248857 | F7: =IF(NOT(ISNUMBER($E7)),"",IF($E7<=1.5,"Yes","No")) -> Yes | G7: =IFERROR(LOOKUP(2,1/((RD_VBP=$A7)*(RD_IREF=$B7)*(RD_RB=Rmax_Summary!$B$37)),RD_VB),"") -> 0.19849498 | H7: =IF(NOT(ISNUMBER($D7)),"",100*ABS($D7-$B7)/$B7) -> 0.75249 | I7: =IF(OR(NOT(ISNUMBER($E7)),NOT(ISNUMBER($H7))),"",$H7-$E7) -> 1.43e-06 | J7: =IF($F7="No","基础恒流误差 >1.5%：原始数据保留，Rmax_Summary 中标记为 N/A（不写作 0）",IF($F7="Yes","低负载区满足 ±1.5%","无数据")) -> 低负载区满足 ±1.5%
A8: 3.3 | B8: 50 | C8: =Rmax_Summary!$B$37/1000 -> 10 | D8: =IFERROR(LOOKUP(2,1/((RD_VBP=$A8)*(RD_IREF=$B8)*(RD_RB=Rmax_Summary!$B$37)),RD_IB),"") -> 49.806301 | E8: =IFERROR(LOOKUP(2,1/((RD_VBP=$A8)*(RD_IREF=$B8)*(RD_RB=Rmax_Summary!$B$37)),RD_IERR),"") -> 0.38739779 | F8: =IF(NOT(ISNUMBER($E8)),"",IF($E8<=1.5,"Yes","No")) -> Yes | G8: =IFERROR(LOOKUP(2,1/((RD_VBP=$A8)*(RD_IREF=$B8)*(RD_RB=Rmax_Summary!$B$37)),RD_VB),"") -> 0.49806297 | H8: =IF(NOT(ISNUMBER($D8)),"",100*ABS($D8-$B8)/$B8) -> 0.387398 | I8: =IF(OR(NOT(ISNUMBER($E8)),NOT(ISNUMBER($H8))),"",$H8-$E8) -> 2.11e-07 | J8: =IF($F8="No","基础恒流误差 >1.5%：原始数据保留，Rmax_Summary 中标记为 N/A（不写作 0）",IF($F8="Yes","低负载区满足 ±1.5%","无数据")) -> 低负载区满足 ±1.5%
A9: 3.3 | B9: 100 | C9: =Rmax_Summary!$B$37/1000 -> 10 | D9: =IFERROR(LOOKUP(2,1/((RD_VBP=$A9)*(RD_IREF=$B9)*(RD_RB=Rmax_Summary!$B$37)),RD_IB),"") -> 99.756435 | E9: =IFERROR(LOOKUP(2,1/((RD_VBP=$A9)*(RD_IREF=$B9)*(RD_RB=Rmax_Summary!$B$37)),RD_IERR),"") -> 0.24356479 | F9: =IF(NOT(ISNUMBER($E9)),"",IF($E9<=1.5,"Yes","No")) -> Yes | G9: =IFERROR(LOOKUP(2,1/((RD_VBP=$A9)*(RD_IREF=$B9)*(RD_RB=Rmax_Summary!$B$37)),RD_VB),"") -> 0.99756431 | H9: =IF(NOT(ISNUMBER($D9)),"",100*ABS($D9-$B9)/$B9) -> 0.243565 | I9: =IF(OR(NOT(ISNUMBER($E9)),NOT(ISNUMBER($H9))),"",$H9-$E9) -> 2.14e-07 | J9: =IF($F9="No","基础恒流误差 >1.5%：原始数据保留，Rmax_Summary 中标记为 N/A（不写作 0）",IF($F9="Yes","低负载区满足 ±1.5%","无数据")) -> 低负载区满足 ±1.5%
A10: 3.3 | B10: 200 | C10: =Rmax_Summary!$B$37/1000 -> 10 | D10: =IFERROR(LOOKUP(2,1/((RD_VBP=$A10)*(RD_IREF=$B10)*(RD_RB=Rmax_Summary!$B$37)),RD_IB),"") -> 199.70089 | E10: =IFERROR(LOOKUP(2,1/((RD_VBP=$A10)*(RD_IREF=$B10)*(RD_RB=Rmax_Summary!$B$37)),RD_IERR),"") -> 0.14955495 | F10: =IF(NOT(ISNUMBER($E10)),"",IF($E10<=1.5,"Yes","No")) -> Yes | G10: =IFERROR(LOOKUP(2,1/((RD_VBP=$A10)*(RD_IREF=$B10)*(RD_RB=Rmax_Summary!$B$37)),RD_VB),"") -> 1.9970089 | H10: =IF(NOT(ISNUMBER($D10)),"",100*ABS($D10-$B10)/$B10) -> 0.149555 | I10: =IF(OR(NOT(ISNUMBER($E10)),NOT(ISNUMBER($H10))),"",$H10-$E10) -> 5.2000007e-08 | J10: =IF($F10="No","基础恒流误差 >1.5%：原始数据保留，Rmax_Summary 中标记为 N/A（不写作 0）",IF($F10="Yes","低负载区满足 ±1.5%","无数据")) -> 低负载区满足 ±1.5%
A11: 5 | B11: 10 | C11: =Rmax_Summary!$B$37/1000 -> 10 | D11: =IFERROR(LOOKUP(2,1/((RD_VBP=$A11)*(RD_IREF=$B11)*(RD_RB=Rmax_Summary!$B$37)),RD_IB),"") -> 9.873922 | E11: =IFERROR(LOOKUP(2,1/((RD_VBP=$A11)*(RD_IREF=$B11)*(RD_RB=Rmax_Summary!$B$37)),RD_IERR),"") -> 1.2607841 | F11: =IF(NOT(ISNUMBER($E11)),"",IF($E11<=1.5,"Yes","No")) -> Yes | G11: =IFERROR(LOOKUP(2,1/((RD_VBP=$A11)*(RD_IREF=$B11)*(RD_RB=Rmax_Summary!$B$37)),RD_VB),"") -> 0.098739207 | H11: =IF(NOT(ISNUMBER($D11)),"",100*ABS($D11-$B11)/$B11) -> 1.26078 | I11: =IF(OR(NOT(ISNUMBER($E11)),NOT(ISNUMBER($H11))),"",$H11-$E11) -> -4.098e-06 | J11: =IF($F11="No","基础恒流误差 >1.5%：原始数据保留，Rmax_Summary 中标记为 N/A（不写作 0）",IF($F11="Yes","低负载区满足 ±1.5%","无数据")) -> 低负载区满足 ±1.5%
A12: 5 | B12: 20 | C12: =Rmax_Summary!$B$37/1000 -> 10 | D12: =IFERROR(LOOKUP(2,1/((RD_VBP=$A12)*(RD_IREF=$B12)*(RD_RB=Rmax_Summary!$B$37)),RD_IB),"") -> 19.853782 | E12: =IFERROR(LOOKUP(2,1/((RD_VBP=$A12)*(RD_IREF=$B12)*(RD_RB=Rmax_Summary!$B$37)),RD_IERR),"") -> 0.7310887 | F12: =IF(NOT(ISNUMBER($E12)),"",IF($E12<=1.5,"Yes","No")) -> Yes | G12: =IFERROR(LOOKUP(2,1/((RD_VBP=$A12)*(RD_IREF=$B12)*(RD_RB=Rmax_Summary!$B$37)),RD_VB),"") -> 0.19853783 | H12: =IF(NOT(ISNUMBER($D12)),"",100*ABS($D12-$B12)/$B12) -> 0.73109 | I12: =IF(OR(NOT(ISNUMBER($E12)),NOT(ISNUMBER($H12))),"",$H12-$E12) -> 1.301e-06 | J12: =IF($F12="No","基础恒流误差 >1.5%：原始数据保留，Rmax_Summary 中标记为 N/A（不写作 0）",IF($F12="Yes","低负载区满足 ±1.5%","无数据")) -> 低负载区满足 ±1.5%
A13: 5 | B13: 50 | C13: =Rmax_Summary!$B$37/1000 -> 10 | D13: =IFERROR(LOOKUP(2,1/((RD_VBP=$A13)*(RD_IREF=$B13)*(RD_RB=Rmax_Summary!$B$37)),RD_IB),"") -> 49.811052 | E13: =IFERROR(LOOKUP(2,1/((RD_VBP=$A13)*(RD_IREF=$B13)*(RD_RB=Rmax_Summary!$B$37)),RD_IERR),"") -> 0.37789685 | F13: =IF(NOT(ISNUMBER($E13)),"",IF($E13<=1.5,"Yes","No")) -> Yes | G13: =IFERROR(LOOKUP(2,1/((RD_VBP=$A13)*(RD_IREF=$B13)*(RD_RB=Rmax_Summary!$B$37)),RD_VB),"") -> 0.49811053 | H13: =IF(NOT(ISNUMBER($D13)),"",100*ABS($D13-$B13)/$B13) -> 0.377896 | I13: =IF(OR(NOT(ISNUMBER($E13)),NOT(ISNUMBER($H13))),"",$H13-$E13) -> -8.5399999e-07 | J13: =IF($F13="No","基础恒流误差 >1.5%：原始数据保留，Rmax_Summary 中标记为 N/A（不写作 0）",IF($F13="Yes","低负载区满足 ±1.5%","无数据")) -> 低负载区满足 ±1.5%
A14: 5 | B14: 100 | C14: =Rmax_Summary!$B$37/1000 -> 10 | D14: =IFERROR(LOOKUP(2,1/((RD_VBP=$A14)*(RD_IREF=$B14)*(RD_RB=Rmax_Summary!$B$37)),RD_IB),"") -> 99.762136 | E14: =IFERROR(LOOKUP(2,1/((RD_VBP=$A14)*(RD_IREF=$B14)*(RD_RB=Rmax_Summary!$B$37)),RD_IERR),"") -> 0.23786358 | F14: =IF(NOT(ISNUMBER($E14)),"",IF($E14<=1.5,"Yes","No")) -> Yes | G14: =IFERROR(LOOKUP(2,1/((RD_VBP=$A14)*(RD_IREF=$B14)*(RD_RB=Rmax_Summary!$B$37)),RD_VB),"") -> 0.99762137 | H14: =IF(NOT(ISNUMBER($D14)),"",100*ABS($D14-$B14)/$B14) -> 0.237864 | I14: =IF(OR(NOT(ISNUMBER($E14)),NOT(ISNUMBER($H14))),"",$H14-$E14) -> 4.19e-07 | J14: =IF($F14="No","基础恒流误差 >1.5%：原始数据保留，Rmax_Summary 中标记为 N/A（不写作 0）",IF($F14="Yes","低负载区满足 ±1.5%","无数据")) -> 低负载区满足 ±1.5%
A15: 5 | B15: 200 | C15: =Rmax_Summary!$B$37/1000 -> 10 | D15: =IFERROR(LOOKUP(2,1/((RD_VBP=$A15)*(RD_IREF=$B15)*(RD_RB=Rmax_Summary!$B$37)),RD_IB),"") -> 199.71004 | E15: =IFERROR(LOOKUP(2,1/((RD_VBP=$A15)*(RD_IREF=$B15)*(RD_RB=Rmax_Summary!$B$37)),RD_IERR),"") -> 0.1449825 | F15: =IF(NOT(ISNUMBER($E15)),"",IF($E15<=1.5,"Yes","No")) -> Yes | G15: =IFERROR(LOOKUP(2,1/((RD_VBP=$A15)*(RD_IREF=$B15)*(RD_RB=Rmax_Summary!$B$37)),RD_VB),"") -> 1.9971004 | H15: =IF(NOT(ISNUMBER($D15)),"",100*ABS($D15-$B15)/$B15) -> 0.1449825 | I15: =IF(OR(NOT(ISNUMBER($E15)),NOT(ISNUMBER($H15))),"",$H15-$E15) -> 9.9999758e-10 | J15: =IF($F15="No","基础恒流误差 >1.5%：原始数据保留，Rmax_Summary 中标记为 N/A（不写作 0）",IF($F15="Yes","低负载区满足 ±1.5%","无数据")) -> 低负载区满足 ±1.5%
A16: 8 | B16: 10 | C16: =Rmax_Summary!$B$37/1000 -> 10 | D16: =IFERROR(LOOKUP(2,1/((RD_VBP=$A16)*(RD_IREF=$B16)*(RD_RB=Rmax_Summary!$B$37)),RD_IB),"") -> 9.878812 | E16: =IFERROR(LOOKUP(2,1/((RD_VBP=$A16)*(RD_IREF=$B16)*(RD_RB=Rmax_Summary!$B$37)),RD_IERR),"") -> 1.2118781 | F16: =IF(NOT(ISNUMBER($E16)),"",IF($E16<=1.5,"Yes","No")) -> Yes | G16: =IFERROR(LOOKUP(2,1/((RD_VBP=$A16)*(RD_IREF=$B16)*(RD_RB=Rmax_Summary!$B$37)),RD_VB),"") -> 0.09878812 | H16: =IF(NOT(ISNUMBER($D16)),"",100*ABS($D16-$B16)/$B16) -> 1.21188 | I16: =IF(OR(NOT(ISNUMBER($E16)),NOT(ISNUMBER($H16))),"",$H16-$E16) -> 1.86e-06 | J16: =IF($F16="No","基础恒流误差 >1.5%：原始数据保留，Rmax_Summary 中标记为 N/A（不写作 0）",IF($F16="Yes","低负载区满足 ±1.5%","无数据")) -> 低负载区满足 ±1.5%
A17: 8 | B17: 20 | C17: =Rmax_Summary!$B$37/1000 -> 10 | D17: =IFERROR(LOOKUP(2,1/((RD_VBP=$A17)*(RD_IREF=$B17)*(RD_RB=Rmax_Summary!$B$37)),RD_IB),"") -> 19.858806 | E17: =IFERROR(LOOKUP(2,1/((RD_VBP=$A17)*(RD_IREF=$B17)*(RD_RB=Rmax_Summary!$B$37)),RD_IERR),"") -> 0.70597183 | F17: =IF(NOT(ISNUMBER($E17)),"",IF($E17<=1.5,"Yes","No")) -> Yes | G17: =IFERROR(LOOKUP(2,1/((RD_VBP=$A17)*(RD_IREF=$B17)*(RD_RB=Rmax_Summary!$B$37)),RD_VB),"") -> 0.19858806 | H17: =IF(NOT(ISNUMBER($D17)),"",100*ABS($D17-$B17)/$B17) -> 0.70597 | I17: =IF(OR(NOT(ISNUMBER($E17)),NOT(ISNUMBER($H17))),"",$H17-$E17) -> -1.826e-06 | J17: =IF($F17="No","基础恒流误差 >1.5%：原始数据保留，Rmax_Summary 中标记为 N/A（不写作 0）",IF($F17="Yes","低负载区满足 ±1.5%","无数据")) -> 低负载区满足 ±1.5%
... A35: 15 | B35: 200 | C35: =Rmax_Summary!$B$37/1000 -> 10 | D35: =IFERROR(LOOKUP(2,1/((RD_VBP=$A35)*(RD_IREF=$B35)*(RD_RB=Rmax_Summary!$B$37)),RD_IB),"") -> 199.7271 | E35: =IFERROR(LOOKUP(2,1/((RD_VBP=$A35)*(RD_IREF=$B35)*(RD_RB=Rmax_Summary!$B$37)),RD_IERR),"") -> 0.13644998 | F35: =IF(NOT(ISNUMBER($E35)),"",IF($E35<=1.5,"Yes","No")) -> Yes | G35: =IFERROR(LOOKUP(2,1/((RD_VBP=$A35)*(RD_IREF=$B35)*(RD_RB=Rmax_Summary!$B$37)),RD_VB),"") -> 1.997271 | H35: =IF(NOT(ISNUMBER($D35)),"",100*ABS($D35-$B35)/$B35) -> 0.13645 | I35: =IF(OR(NOT(ISNUMBER($E35)),NOT(ISNUMBER($H35))),"",$H35-$E35) -> 1.9999996e-08 | J35: =IF($F35="No","基础恒流误差 >1.5%：原始数据保留，Rmax_Summary 中标记为 N/A（不写作 0）",IF($F35="Yes","低负载区满足 ±1.5%","无数据")) -> 低负载区满足 ±1.5%
A37: B. 恒流误差 IERR (%) 随负载变化 — 绿 = 仍在 ±1.5% 恒流区 ；红 = 已超出 ±1.5% ；用于判断各负载下何时掉出恒流区
A39: VBP_V | B39: Target_I_uA | C39: 10000 | D39: 20000 | E39: 50000 | F39: 100000 | G39: 200000 | H39: 500000 | I39: 1000000 | J39: 10000000 | K39: n_PASS (共 1828 点)
A40: 3.3 | B40: 10 | C40: =IFERROR(LOOKUP(2,1/((RD_VBP=$A40)*(RD_IREF=$B40)*(RD_RB=C$39)),RD_IERR),"") -> 1.3020312 | D40: =IFERROR(LOOKUP(2,1/((RD_VBP=$A40)*(RD_IREF=$B40)*(RD_RB=D$39)),RD_IERR),"") -> 1.3049604 | E40: =IFERROR(LOOKUP(2,1/((RD_VBP=$A40)*(RD_IREF=$B40)*(RD_RB=E$39)),RD_IERR),"") -> 1.3142293 | F40: =IFERROR(LOOKUP(2,1/((RD_VBP=$A40)*(RD_IREF=$B40)*(RD_RB=F$39)),RD_IERR),"") -> 1.3315699 | G40: =IFERROR(LOOKUP(2,1/((RD_VBP=$A40)*(RD_IREF=$B40)*(RD_RB=G$39)),RD_IERR),"") -> 1.3770159 | H40: =IFERROR(LOOKUP(2,1/((RD_VBP=$A40)*(RD_IREF=$B40)*(RD_RB=H$39)),RD_IERR),"") -> 34.41354 | I40: =IFERROR(LOOKUP(2,1/((RD_VBP=$A40)*(RD_IREF=$B40)*(RD_RB=I$39)),RD_IERR),"") -> 67.108591 | J40: =IFERROR(LOOKUP(2,1/((RD_VBP=$A40)*(RD_IREF=$B40)*(RD_RB=J$39)),RD_IERR),"") -> 96.701973 | K40: =SUMPRODUCT((RD_VBP=$A40)*(RD_IREF=$B40)*(RD_PASS=1)) -> 225
A41: 3.3 | B41: 20 | C41: =IFERROR(LOOKUP(2,1/((RD_VBP=$A41)*(RD_IREF=$B41)*(RD_RB=C$39)),RD_IERR),"") -> 0.75248857 | D41: =IFERROR(LOOKUP(2,1/((RD_VBP=$A41)*(RD_IREF=$B41)*(RD_RB=D$39)),RD_IERR),"") -> 0.75560732 | E41: =IFERROR(LOOKUP(2,1/((RD_VBP=$A41)*(RD_IREF=$B41)*(RD_RB=E$39)),RD_IERR),"") -> 0.76612684 | F41: =IFERROR(LOOKUP(2,1/((RD_VBP=$A41)*(RD_IREF=$B41)*(RD_RB=F$39)),RD_IERR),"") -> 0.78957765 | G41: =IFERROR(LOOKUP(2,1/((RD_VBP=$A41)*(RD_IREF=$B41)*(RD_RB=G$39)),RD_IERR),"") -> 18.744561 | H41: =IFERROR(LOOKUP(2,1/((RD_VBP=$A41)*(RD_IREF=$B41)*(RD_RB=H$39)),RD_IERR),"") -> 67.20677 | I41: =IFERROR(LOOKUP(2,1/((RD_VBP=$A41)*(RD_IREF=$B41)*(RD_RB=I$39)),RD_IERR),"") -> 83.554296 | J41: =IFERROR(LOOKUP(2,1/((RD_VBP=$A41)*(RD_IREF=$B41)*(RD_RB=J$39)),RD_IERR),"") -> 98.350986 | K41: =SUMPRODUCT((RD_VBP=$A41)*(RD_IREF=$B41)*(RD_PASS=1)) -> 194
A42: 3.3 | B42: 50 | C42: =IFERROR(LOOKUP(2,1/((RD_VBP=$A42)*(RD_IREF=$B42)*(RD_RB=C$39)),RD_IERR),"") -> 0.38739779 | D42: =IFERROR(LOOKUP(2,1/((RD_VBP=$A42)*(RD_IREF=$B42)*(RD_RB=D$39)),RD_IERR),"") -> 0.39112404 | E42: =IFERROR(LOOKUP(2,1/((RD_VBP=$A42)*(RD_IREF=$B42)*(RD_RB=E$39)),RD_IERR),"") -> 0.40835071 | F42: =IFERROR(LOOKUP(2,1/((RD_VBP=$A42)*(RD_IREF=$B42)*(RD_RB=F$39)),RD_IERR),"") -> 35.943229 | G42: =IFERROR(LOOKUP(2,1/((RD_VBP=$A42)*(RD_IREF=$B42)*(RD_RB=G$39)),RD_IERR),"") -> 67.497824 | H42: =IFERROR(LOOKUP(2,1/((RD_VBP=$A42)*(RD_IREF=$B42)*(RD_RB=H$39)),RD_IERR),"") -> 86.882708 | I42: =IFERROR(LOOKUP(2,1/((RD_VBP=$A42)*(RD_IREF=$B42)*(RD_RB=I$39)),RD_IERR),"") -> 93.421718 | J42: =IFERROR(LOOKUP(2,1/((RD_VBP=$A42)*(RD_IREF=$B42)*(RD_RB=J$39)),RD_IERR),"") -> 99.340395 | K42: =SUMPRODUCT((RD_VBP=$A42)*(RD_IREF=$B42)*(RD_PASS=1)) -> 91
A43: 3.3 | B43: 100 | C43: =IFERROR(LOOKUP(2,1/((RD_VBP=$A43)*(RD_IREF=$B43)*(RD_RB=C$39)),RD_IERR),"") -> 0.24356479 | D43: =IFERROR(LOOKUP(2,1/((RD_VBP=$A43)*(RD_IREF=$B43)*(RD_RB=D$39)),RD_IERR),"") -> 0.24890941 | E43: =IFERROR(LOOKUP(2,1/((RD_VBP=$A43)*(RD_IREF=$B43)*(RD_RB=E$39)),RD_IERR),"") -> 37.757973 | F43: =IFERROR(LOOKUP(2,1/((RD_VBP=$A43)*(RD_IREF=$B43)*(RD_RB=F$39)),RD_IERR),"") -> 67.971613 | G43: =IFERROR(LOOKUP(2,1/((RD_VBP=$A43)*(RD_IREF=$B43)*(RD_RB=G$39)),RD_IERR),"") -> 83.748912 | H43: =IFERROR(LOOKUP(2,1/((RD_VBP=$A43)*(RD_IREF=$B43)*(RD_RB=H$39)),RD_IERR),"") -> 93.441354 | I43: =IFERROR(LOOKUP(2,1/((RD_VBP=$A43)*(RD_IREF=$B43)*(RD_RB=I$39)),RD_IERR),"") -> 96.710859 | J43: =IFERROR(LOOKUP(2,1/((RD_VBP=$A43)*(RD_IREF=$B43)*(RD_RB=J$39)),RD_IERR),"") -> 99.670197 | K43: =SUMPRODUCT((RD_VBP=$A43)*(RD_IREF=$B43)*(RD_PASS=1)) -> 60
A44: 3.3 | B44: 200 | C44: =IFERROR(LOOKUP(2,1/((RD_VBP=$A44)*(RD_IREF=$B44)*(RD_RB=C$39)),RD_IERR),"") -> 0.14955495 | D44: =IFERROR(LOOKUP(2,1/((RD_VBP=$A44)*(RD_IREF=$B44)*(RD_RB=D$39)),RD_IERR),"") -> 28.293262 | E44: =IFERROR(LOOKUP(2,1/((RD_VBP=$A44)*(RD_IREF=$B44)*(RD_RB=E$39)),RD_IERR),"") -> 68.878987 | F44: =IFERROR(LOOKUP(2,1/((RD_VBP=$A44)*(RD_IREF=$B44)*(RD_RB=F$39)),RD_IERR),"") -> 83.985806 | G44: =IFERROR(LOOKUP(2,1/((RD_VBP=$A44)*(RD_IREF=$B44)*(RD_RB=G$39)),RD_IERR),"") -> 91.874456 | H44: =IFERROR(LOOKUP(2,1/((RD_VBP=$A44)*(RD_IREF=$B44)*(RD_RB=H$39)),RD_IERR),"") -> 96.720677 | I44: =IFERROR(LOOKUP(2,1/((RD_VBP=$A44)*(RD_IREF=$B44)*(RD_RB=I$39)),RD_IERR),"") -> 98.35543 | J44: =IFERROR(LOOKUP(2,1/((RD_VBP=$A44)*(RD_IREF=$B44)*(RD_RB=J$39)),RD_IERR),"") -> 99.835099 | K44: =SUMPRODUCT((RD_VBP=$A44)*(RD_IREF=$B44)*(RD_PASS=1)) -> 35
A45: 5 | B45: 10 | C45: =IFERROR(LOOKUP(2,1/((RD_VBP=$A45)*(RD_IREF=$B45)*(RD_RB=C$39)),RD_IERR),"") -> 1.2607841 | D45: =IFERROR(LOOKUP(2,1/((RD_VBP=$A45)*(RD_IREF=$B45)*(RD_RB=D$39)),RD_IERR),"") -> 1.2628189 | E45: =IFERROR(LOOKUP(2,1/((RD_VBP=$A45)*(RD_IREF=$B45)*(RD_RB=E$39)),RD_IERR),"") -> 1.2691475 | F45: =IFERROR(LOOKUP(2,1/((RD_VBP=$A45)*(RD_IREF=$B45)*(RD_RB=F$39)),RD_IERR),"") -> 1.2805408 | G45: =IFERROR(LOOKUP(2,1/((RD_VBP=$A45)*(RD_IREF=$B45)*(RD_RB=G$39)),RD_IERR),"") -> 1.3074192 | H45: =IFERROR(LOOKUP(2,1/((RD_VBP=$A45)*(RD_IREF=$B45)*(RD_RB=H$39)),RD_IERR),"") -> 1.5824046 | I45: =IFERROR(LOOKUP(2,1/((RD_VBP=$A45)*(RD_IREF=$B45)*(RD_RB=I$39)),RD_IERR),"") -> 50.159486 | J45: =IFERROR(LOOKUP(2,1/((RD_VBP=$A45)*(RD_IREF=$B45)*(RD_RB=J$39)),RD_IERR),"") -> 95.002483 | K45: =SUMPRODUCT((RD_VBP=$A45)*(RD_IREF=$B45)*(RD_PASS=1)) -> 235
A46: 5 | B46: 20 | C46: =IFERROR(LOOKUP(2,1/((RD_VBP=$A46)*(RD_IREF=$B46)*(RD_RB=C$39)),RD_IERR),"") -> 0.7310887 | D46: =IFERROR(LOOKUP(2,1/((RD_VBP=$A46)*(RD_IREF=$B46)*(RD_RB=D$39)),RD_IERR),"") -> 0.73322017 | E46: =IFERROR(LOOKUP(2,1/((RD_VBP=$A46)*(RD_IREF=$B46)*(RD_RB=E$39)),RD_IERR),"") -> 0.74013208 | F46: =IFERROR(LOOKUP(2,1/((RD_VBP=$A46)*(RD_IREF=$B46)*(RD_RB=F$39)),RD_IERR),"") -> 0.75389299 | G46: =IFERROR(LOOKUP(2,1/((RD_VBP=$A46)*(RD_IREF=$B46)*(RD_RB=G$39)),RD_IERR),"") -> 0.79871526 | H46: =IFERROR(LOOKUP(2,1/((RD_VBP=$A46)*(RD_IREF=$B46)*(RD_RB=H$39)),RD_IERR),"") -> 50.308259 | I46: =IFERROR(LOOKUP(2,1/((RD_VBP=$A46)*(RD_IREF=$B46)*(RD_RB=I$39)),RD_IERR),"") -> 75.079744 | J46: =IFERROR(LOOKUP(2,1/((RD_VBP=$A46)*(RD_IREF=$B46)*(RD_RB=J$39)),RD_IERR),"") -> 97.501242 | K46: =SUMPRODUCT((RD_VBP=$A46)*(RD_IREF=$B46)*(RD_PASS=1)) -> 249
A47: 5 | B47: 50 | C47: =IFERROR(LOOKUP(2,1/((RD_VBP=$A47)*(RD_IREF=$B47)*(RD_RB=C$39)),RD_IERR),"") -> 0.37789685 | D47: =IFERROR(LOOKUP(2,1/((RD_VBP=$A47)*(RD_IREF=$B47)*(RD_RB=D$39)),RD_IERR),"") -> 0.38030918 | E47: =IFERROR(LOOKUP(2,1/((RD_VBP=$A47)*(RD_IREF=$B47)*(RD_RB=E$39)),RD_IERR),"") -> 0.38953941 | F47: =IFERROR(LOOKUP(2,1/((RD_VBP=$A47)*(RD_IREF=$B47)*(RD_RB=F$39)),RD_IERR),"") -> 2.9345199 | G47: =IFERROR(LOOKUP(2,1/((RD_VBP=$A47)*(RD_IREF=$B47)*(RD_RB=G$39)),RD_IERR),"") -> 50.7493 | H47: =IFERROR(LOOKUP(2,1/((RD_VBP=$A47)*(RD_IREF=$B47)*(RD_RB=H$39)),RD_IERR),"") -> 80.123303 | I47: =IFERROR(LOOKUP(2,1/((RD_VBP=$A47)*(RD_IREF=$B47)*(RD_RB=I$39)),RD_IERR),"") -> 90.031897 | J47: =IFERROR(LOOKUP(2,1/((RD_VBP=$A47)*(RD_IREF=$B47)*(RD_RB=J$39)),RD_IERR),"") -> 99.000497 | K47: =SUMPRODUCT((RD_VBP=$A47)*(RD_IREF=$B47)*(RD_PASS=1)) -> 138
A48: 5 | B48: 100 | C48: =IFERROR(LOOKUP(2,1/((RD_VBP=$A48)*(RD_IREF=$B48)*(RD_RB=C$39)),RD_IERR),"") -> 0.23786358 | D48: =IFERROR(LOOKUP(2,1/((RD_VBP=$A48)*(RD_IREF=$B48)*(RD_RB=D$39)),RD_IERR),"") -> 0.24087743 | E48: =IFERROR(LOOKUP(2,1/((RD_VBP=$A48)*(RD_IREF=$B48)*(RD_RB=E$39)),RD_IERR),"") -> 5.6846282 | F48: =IFERROR(LOOKUP(2,1/((RD_VBP=$A48)*(RD_IREF=$B48)*(RD_RB=F$39)),RD_IERR),"") -> 51.46726 | G48: =IFERROR(LOOKUP(2,1/((RD_VBP=$A48)*(RD_IREF=$B48)*(RD_RB=G$39)),RD_IERR),"") -> 75.37465 | H48: =IFERROR(LOOKUP(2,1/((RD_VBP=$A48)*(RD_IREF=$B48)*(RD_RB=H$39)),RD_IERR),"") -> 90.061651 | I48: =IFERROR(LOOKUP(2,1/((RD_VBP=$A48)*(RD_IREF=$B48)*(RD_RB=I$39)),RD_IERR),"") -> 95.015949 | J48: =IFERROR(LOOKUP(2,1/((RD_VBP=$A48)*(RD_IREF=$B48)*(RD_RB=J$39)),RD_IERR),"") -> 99.500248 | K48: =SUMPRODUCT((RD_VBP=$A48)*(RD_IREF=$B48)*(RD_PASS=1)) -> 75
A49: 5 | B49: 200 | C49: =IFERROR(LOOKUP(2,1/((RD_VBP=$A49)*(RD_IREF=$B49)*(RD_RB=C$39)),RD_IERR),"") -> 0.1449825 | D49: =IFERROR(LOOKUP(2,1/((RD_VBP=$A49)*(RD_IREF=$B49)*(RD_RB=D$39)),RD_IERR),"") -> 0.15098155 | E49: =IFERROR(LOOKUP(2,1/((RD_VBP=$A49)*(RD_IREF=$B49)*(RD_RB=E$39)),RD_IERR),"") -> 52.842296 | F49: =IFERROR(LOOKUP(2,1/((RD_VBP=$A49)*(RD_IREF=$B49)*(RD_RB=F$39)),RD_IERR),"") -> 75.73363 | G49: =IFERROR(LOOKUP(2,1/((RD_VBP=$A49)*(RD_IREF=$B49)*(RD_RB=G$39)),RD_IERR),"") -> 87.687325 | H49: =IFERROR(LOOKUP(2,1/((RD_VBP=$A49)*(RD_IREF=$B49)*(RD_RB=H$39)),RD_IERR),"") -> 95.030826 | I49: =IFERROR(LOOKUP(2,1/((RD_VBP=$A49)*(RD_IREF=$B49)*(RD_RB=I$39)),RD_IERR),"") -> 97.507974 | J49: =IFERROR(LOOKUP(2,1/((RD_VBP=$A49)*(RD_IREF=$B49)*(RD_RB=J$39)),RD_IERR),"") -> 99.750124 | K49: =SUMPRODUCT((RD_VBP=$A49)*(RD_IREF=$B49)*(RD_PASS=1)) -> 42
A50: 8 | B50: 10 | C50: =IFERROR(LOOKUP(2,1/((RD_VBP=$A50)*(RD_IREF=$B50)*(RD_RB=C$39)),RD_IERR),"") -> 1.2118781 | D50: =IFERROR(LOOKUP(2,1/((RD_VBP=$A50)*(RD_IREF=$B50)*(RD_RB=D$39)),RD_IERR),"") -> 1.2131999 | E50: =IFERROR(LOOKUP(2,1/((RD_VBP=$A50)*(RD_IREF=$B50)*(RD_RB=E$39)),RD_IERR),"") -> 1.2172584 | F50: =IFERROR(LOOKUP(2,1/((RD_VBP=$A50)*(RD_IREF=$B50)*(RD_RB=F$39)),RD_IERR),"") -> 1.2243601 | G50: =IFERROR(LOOKUP(2,1/((RD_VBP=$A50)*(RD_IREF=$B50)*(RD_RB=G$39)),RD_IERR),"") -> 1.24004 | H50: =IFERROR(LOOKUP(2,1/((RD_VBP=$A50)*(RD_IREF=$B50)*(RD_RB=H$39)),RD_IERR),"") -> 1.3064607 | I50: =IFERROR(LOOKUP(2,1/((RD_VBP=$A50)*(RD_IREF=$B50)*(RD_RB=I$39)),RD_IERR),"") -> 20.249302 | J50: =IFERROR(LOOKUP(2,1/((RD_VBP=$A50)*(RD_IREF=$B50)*(RD_RB=J$39)),RD_IERR),"") -> 92.003384 | K50: =SUMPRODUCT((RD_VBP=$A50)*(RD_IREF=$B50)*(RD_PASS=1)) -> 266
A51: 8 | B51: 20 | C51: =IFERROR(LOOKUP(2,1/((RD_VBP=$A51)*(RD_IREF=$B51)*(RD_RB=C$39)),RD_IERR),"") -> 0.70597183 | D51: =IFERROR(LOOKUP(2,1/((RD_VBP=$A51)*(RD_IREF=$B51)*(RD_RB=D$39)),RD_IERR),"") -> 0.70733882 | E51: =IFERROR(LOOKUP(2,1/((RD_VBP=$A51)*(RD_IREF=$B51)*(RD_RB=E$39)),RD_IERR),"") -> 0.71164512 | F51: =IFERROR(LOOKUP(2,1/((RD_VBP=$A51)*(RD_IREF=$B51)*(RD_RB=F$39)),RD_IERR),"") -> 0.71962797 | G51: =IFERROR(LOOKUP(2,1/((RD_VBP=$A51)*(RD_IREF=$B51)*(RD_RB=G$39)),RD_IERR),"") -> 0.7399586 | H51: =IFERROR(LOOKUP(2,1/((RD_VBP=$A51)*(RD_IREF=$B51)*(RD_RB=H$39)),RD_IERR),"") -> 20.487357 | I51: =IFERROR(LOOKUP(2,1/((RD_VBP=$A51)*(RD_IREF=$B51)*(RD_RB=I$39)),RD_IERR),"") -> 60.124651 | J51: =IFERROR(LOOKUP(2,1/((RD_VBP=$A51)*(RD_IREF=$B51)*(RD_RB=J$39)),RD_IERR),"") -> 96.001692 | K51: =SUMPRODUCT((RD_VBP=$A51)*(RD_IREF=$B51)*(RD_PASS=1)) -> 252
... A69: 15 | B69: 200 | C69: =IFERROR(LOOKUP(2,1/((RD_VBP=$A69)*(RD_IREF=$B69)*(RD_RB=C$39)),RD_IERR),"") -> 0.13644998 | D69: =IFERROR(LOOKUP(2,1/((RD_VBP=$A69)*(RD_IREF=$B69)*(RD_RB=D$39)),RD_IERR),"") -> 0.13743061 | E69: =IFERROR(LOOKUP(2,1/((RD_VBP=$A69)*(RD_IREF=$B69)*(RD_RB=E$39)),RD_IERR),"") -> 0.14204629 | F69: =IFERROR(LOOKUP(2,1/((RD_VBP=$A69)*(RD_IREF=$B69)*(RD_RB=F$39)),RD_IERR),"") -> 27.191748 | G69: =IFERROR(LOOKUP(2,1/((RD_VBP=$A69)*(RD_IREF=$B69)*(RD_RB=G$39)),RD_IERR),"") -> 63.057168 | H69: =IFERROR(LOOKUP(2,1/((RD_VBP=$A69)*(RD_IREF=$B69)*(RD_RB=H$39)),RD_IERR),"") -> 85.090526 | I69: =IFERROR(LOOKUP(2,1/((RD_VBP=$A69)*(RD_IREF=$B69)*(RD_RB=I$39)),RD_IERR),"") -> 92.522944 | J69: =IFERROR(LOOKUP(2,1/((RD_VBP=$A69)*(RD_IREF=$B69)*(RD_RB=J$39)),RD_IERR),"") -> 99.250274 | K69: =SUMPRODUCT((RD_VBP=$A69)*(RD_IREF=$B69)*(RD_PASS=1)) -> 98

Sheet Chart_Source
A1: Chart_Source — 图表源数据（由脚本生成，供 Charts / Charts_I_vs_R 引用；请勿手工改动）
A2: Block 1：各目标电流的 −1.5% 限值线（x = 扫描区间两端, y = 0.985 × Target） | B2: 10 µA −1.5% (µA) | C2: 20 µA −1.5% (µA) | D2: 50 µA −1.5% (µA) | E2: 100 µA −1.5% (µA) | F2: 200 µA −1.5% (µA)
A3: 10 | B3: =Rmax_Summary!B$6*0.985 -> 9.85 | C3: =Rmax_Summary!C$6*0.985 -> 19.7 | D3: =Rmax_Summary!D$6*0.985 -> 49.25 | E3: =Rmax_Summary!E$6*0.985 -> 98.5 | F3: =Rmax_Summary!F$6*0.985 -> 197
A4: 10000 | B4: =B3 -> 9.85 | C4: =C3 -> 19.7 | D4: =D3 -> 49.25 | E4: =E3 -> 98.5 | F4: =F3 -> 197
A6: Block 2：仅知下限的点（在扫描上限处仍 PASS）→ 图① 红色 × 标记
A7: VBP_V | B7: Rmax_kOhm (≥下限) | C7: IREF_uA | D7: 备注
A8: （本次两次扫描合并后无此情形：除 10 µA 外全部组合已在扫描上限内定界）
A9: Block 3：扫描上限参考线 → 图① 灰色虚线
A10: VBP_V | B10: Scan_limit_kOhm
A11: 3.3 | B11: 10000
A12: 15 | B12: 10000

Sheet Charts
A1: Charts — 图① Maximum BONE Resistance vs BONE_P Voltage
N2: 状态表（与 Rmax_Summary Block C 同步）
N3: BONE_P / V | O3: 10 | P3: 20 | Q3: 50 | R3: 100 | S3: 200
N4: =Rmax_Summary!$A$29 -> 3.3 | O4: =Rmax_Summary!B29 -> 精确 | P4: =Rmax_Summary!C29 -> 精确 | Q4: =Rmax_Summary!D29 -> 精确 | R4: =Rmax_Summary!E29 -> 精确 | S4: =Rmax_Summary!F29 -> 精确
N5: =Rmax_Summary!$A$30 -> 5 | O5: =Rmax_Summary!B30 -> 精确 | P5: =Rmax_Summary!C30 -> 精确 | Q5: =Rmax_Summary!D30 -> 精确 | R5: =Rmax_Summary!E30 -> 精确 | S5: =Rmax_Summary!F30 -> 精确
N6: =Rmax_Summary!$A$31 -> 8 | O6: =Rmax_Summary!B31 -> 精确 | P6: =Rmax_Summary!C31 -> 精确 | Q6: =Rmax_Summary!D31 -> 精确 | R6: =Rmax_Summary!E31 -> 精确 | S6: =Rmax_Summary!F31 -> 精确
N7: =Rmax_Summary!$A$32 -> 10 | O7: =Rmax_Summary!B32 -> 精确 | P7: =Rmax_Summary!C32 -> 精确 | Q7: =Rmax_Summary!D32 -> 精确 | R7: =Rmax_Summary!E32 -> 精确 | S7: =Rmax_Summary!F32 -> 精确
N8: =Rmax_Summary!$A$33 -> 12 | O8: =Rmax_Summary!B33 -> 精确 | P8: =Rmax_Summary!C33 -> 精确 | Q8: =Rmax_Summary!D33 -> 精确 | R8: =Rmax_Summary!E33 -> 精确 | S8: =Rmax_Summary!F33 -> 精确
N9: =Rmax_Summary!$A$34 -> 15 | O9: =Rmax_Summary!B34 -> 精确 | P9: =Rmax_Summary!C34 -> 精确 | Q9: =Rmax_Summary!D34 -> 精确 | R9: =Rmax_Summary!E34 -> 精确 | S9: =Rmax_Summary!F34 -> 精确
N11: 绘图规则（务必遵守）
N12: · 实线 + 圆点 | O12: 仅连接【实测精确】Rmax（RB 继续增大即 FAIL）；三次扫描合并后24/30 组合已测得真实临界值
N13: · 红色 × 标记 | O13: 仅在下限未知时出现（在上限处仍 PASS）。本次合并后【无此情形】，故图中没有 × 标记
N14: · 灰色虚线 | O14: 扫描上限参考线，仅当存在“≥上限”的点时才绘制；本次无此类点，故不绘制
N15: · 10 µA | O15: 10 µA 的低负载基础误差为 1.302% ~ 1.144%，与 ±1.5% 判据的关系见 Rmax_Summary 与状态表
N16: · 无插值 | O16: 未对缺失点插值或外推；空白即未仿真，不补数
N17: 需细扫的组合（窗口见 Boundary_Detail）
N18: VBP=3.3 V, 10 µA → 318 ~ 318 kΩ
N19: VBP=3.3 V, 20 µA → 164 ~ 164 kΩ
N20: VBP=3.3 V, 50 µA → 64 ~ 64 kΩ
N21: VBP=3.3 V, 100 µA → 30 ~ 30 kΩ
N22: VBP=3.3 V, 200 µA → 14 ~ 14 kΩ
N23: VBP=5 V, 10 µA → 490 ~ 490 kΩ
N24: VBP=5 V, 20 µA → 251 ~ 251 kΩ
N25: VBP=5 V, 50 µA → 98 ~ 98 kΩ
N26: VBP=5 V, 100 µA → 48 ~ 48 kΩ
N27: VBP=5 V, 200 µA → 22 ~ 22 kΩ
N28: VBP=8 V, 10 µA → 794 ~ 794 kΩ
... N47: VBP=15 V, 200 µA → 73 ~ 73 kΩ

Sheet Charts_I_vs_R
